Workbook
Name Matières: 'Créneaux'!$I$2:$I$39
Name CréneauxM: 'Créneaux'!$J$2:$N$9
Name Matière: 'Créneaux'!$A$2:$A$39
Name CollesP: Colles!$B$34:$S$49
Name CréneauxP: 'Créneaux'!$J$18:$N$25
Name TPInfo: TPTD!$A$10:$R$12
Name CollesA: Colles!$B$18:$S$33
Name Semaines: TPTD!$A$1:$R$1
Name Colleurs: 'Créneaux'!$B$2:$B$39
Name CréneauxS: 'Créneaux'!$J$34:$N$37
Name CollesF: Colles!$B$82:$S$97
Name CréneauxF: 'Créneaux'!$J$38:$N$39
Name DatesSemaines: Semaines!$A$1:$C$16
Name CollesM: Colles!$B$2:$S$17
Name TPSI: TPTD!$A$6:$R$8
Name TPPhysique: TPTD!$A$3:$R$4
Name CollesS: Colles!$B$66:$S$81
Name TDChimie: TPTD!$A$14:$R$15
Name CréneauxA: 'Créneaux'!$J$10:$N$17
Name CréneauxC: 'Créneaux'!$J$26:$N$33
Name Groupes: 'Trinômes'!$F$2:$H$17
Name LV2Jours: 'LV2'!$A$2:$B$4
Name Étudiants: 'Trinômes'!$A$2:$D$48
Name CollesC: Colles!$B$50:$S$65

Sheet Colloscope
G1: =INDIRECT("Semaines!"&ADDRESS(column()-column($E$1)-countif($F$1:F$1,"")+1,2,4)) -> 3 | H1: =INDIRECT("Semaines!"&ADDRESS(column()-column($E$1)-countif($F$1:G$1,"")+1,2,4)) -> 4 | I1: =INDIRECT("Semaines!"&ADDRESS(column()-column($E$1)-countif($F$1:H$1,"")+1,2,4)) -> 5 | J1: =INDIRECT("Semaines!"&ADDRESS(column()-column($E$1)-countif($F$1:I$1,"")+1,2,4)) -> 6 | K1: =INDIRECT("Semaines!"&ADDRESS(column()-column($E$1)-countif($F$1:J$1,"")+1,2,4)) -> 7 | M1: =INDIRECT("Semaines!"&ADDRESS(column()-column($E$1)-countif($F$1:L$1,"")+1,2,4)) -> 8 | N1: =INDIRECT("Semaines!"&ADDRESS(column()-column($E$1)-countif($F$1:M$1,"")+1,2,4)) -> 9 | O1: =INDIRECT("Semaines!"&ADDRESS(column()-column($E$1)-countif($F$1:N$1,"")+1,2,4)) -> 10 | P1: =INDIRECT("Semaines!"&ADDRESS(column()-column($E$1)-countif($F$1:O$1,"")+1,2,4)) -> 11 | Q1: =INDIRECT("Semaines!"&ADDRESS(column()-column($E$1)-countif($F$1:P$1,"")+1,2,4)) -> 12 | R1: =INDIRECT("Semaines!"&ADDRESS(column()-column($E$1)-countif($F$1:Q$1,"")+1,2,4)) -> 13 | S1: =INDIRECT("Semaines!"&ADDRESS(column()-column($E$1)-countif($F$1:R$1,"")+1,2,4)) -> 14 | U1: =INDIRECT("Semaines!"&ADDRESS(column()-column($E$1)-countif($F$1:T$1,"")+1,2,4)) -> 15 | V1: =INDIRECT("Semaines!"&ADDRESS(column()-column($E$1)-countif($F$1:U$1,"")+1,2,4)) -> 16 | W1: =INDIRECT("Semaines!"&ADDRESS(column()-column($E$1)-countif($F$1:V$1,"")+1,2,4)) -> 17
F2: Lundi | G2: =INDIRECT("Semaines!"&ADDRESS(column()-column($E$1)-countif($F$1:F$1,"")+1,1,4)) -> 46279 | H2: =INDIRECT("Semaines!"&ADDRESS(column()-column($E$1)-countif($F$1:G$1,"")+1,1,4)) -> 46286 | I2: =INDIRECT("Semaines!"&ADDRESS(column()-column($E$1)-countif($F$1:H$1,"")+1,1,4)) -> 46293 | J2: =INDIRECT("Semaines!"&ADDRESS(column()-column($E$1)-countif($F$1:I$1,"")+1,1,4)) -> 46300 | K2: =INDIRECT("Semaines!"&ADDRESS(column()-column($E$1)-countif($F$1:J$1,"")+1,1,4)) -> 46307 | M2: =INDIRECT("Semaines!"&ADDRESS(column()-column($E$1)-countif($F$1:L$1,"")+1,1,4)) -> 46328 | N2: =INDIRECT("Semaines!"&ADDRESS(column()-column($E$1)-countif($F$1:M$1,"")+1,1,4)) -> 46335 | O2: =INDIRECT("Semaines!"&ADDRESS(column()-column($E$1)-countif($F$1:N$1,"")+1,1,4)) -> 46342 | P2: =INDIRECT("Semaines!"&ADDRESS(column()-column($E$1)-countif($F$1:O$1,"")+1,1,4)) -> 46349 | Q2: =INDIRECT("Semaines!"&ADDRESS(column()-column($E$1)-countif($F$1:P$1,"")+1,1,4)) -> 46356 | R2: =INDIRECT("Semaines!"&ADDRESS(column()-column($E$1)-countif($F$1:Q$1,"")+1,1,4)) -> 46363 | S2: =INDIRECT("Semaines!"&ADDRESS(column()-column($E$1)-countif($F$1:R$1,"")+1,1,4)) -> 46370 | U2: =INDIRECT("Semaines!"&ADDRESS(column()-column($E$1)-countif($F$1:T$1,"")+1,1,4)) -> 46391 | V2: =INDIRECT("Semaines!"&ADDRESS(column()-column($E$1)-countif($F$1:U$1,"")+1,1,4)) -> 46398 | W2: =INDIRECT("Semaines!"&ADDRESS(column()-column($E$1)-countif($F$1:V$1,"")+1,1,4)) -> 46405 | Z2: TD | AB2: Créneau | AC2: Groupe
F3: Semaine | G3: =G$1&INDIRECT("Semaines!"&ADDRESS(column()-column($E$1)-countif($F$1:F$1,"")+1,3,4)) -> 3B | H3: =H$1&INDIRECT("Semaines!"&ADDRESS(column()-column($E$1)-countif($F$1:G$1,"")+1,3,4)) -> 4A | I3: =I$1&INDIRECT("Semaines!"&ADDRESS(column()-column($E$1)-countif($F$1:H$1,"")+1,3,4)) -> 5B | J3: =J$1&INDIRECT("Semaines!"&ADDRESS(column()-column($E$1)-countif($F$1:I$1,"")+1,3,4)) -> 6A | K3: =K$1&INDIRECT("Semaines!"&ADDRESS(column()-column($E$1)-countif($F$1:J$1,"")+1,3,4)) -> 7B | M3: =M$1&INDIRECT("Semaines!"&ADDRESS(column()-column($E$1)-countif($F$1:L$1,"")+1,3,4)) -> 8A | N3: =N$1&INDIRECT("Semaines!"&ADDRESS(column()-column($E$1)-countif($F$1:M$1,"")+1,3,4)) -> 9B | O3: =O$1&INDIRECT("Semaines!"&ADDRESS(column()-column($E$1)-countif($F$1:N$1,"")+1,3,4)) -> 10A | P3: =P$1&INDIRECT("Semaines!"&ADDRESS(column()-column($E$1)-countif($F$1:O$1,"")+1,3,4)) -> 11B | Q3: =Q$1&INDIRECT("Semaines!"&ADDRESS(column()-column($E$1)-countif($F$1:P$1,"")+1,3,4)) -> 12A | R3: =R$1&INDIRECT("Semaines!"&ADDRESS(column()-column($E$1)-countif($F$1:Q$1,"")+1,3,4)) -> 13B | S3: =S$1&INDIRECT("Semaines!"&ADDRESS(column()-column($E$1)-countif($F$1:R$1,"")+1,3,4)) -> 14A | U3: =U$1&INDIRECT("Semaines!"&ADDRESS(column()-column($E$1)-countif($F$1:T$1,"")+1,3,4)) -> 15B | V3: =V$1&INDIRECT("Semaines!"&ADDRESS(column()-column($E$1)-countif($F$1:U$1,"")+1,3,4)) -> 16A | W3: =W$1&INDIRECT("Semaines!"&ADDRESS(column()-column($E$1)-countif($F$1:V$1,"")+1,3,4)) -> 17B | Z3: TD Maths | AB3: Lundi 11h | AC3: G2
D4: SI | AB4: Lundi 12h | AC4: G1
B5: 8 | D5: TP1 | E5: Mardi | F5: =B5&"h" -> 8h | G5: =if(sumproduct((TPTD!B$6:B$8=$B5),TPTD!$A$6:$A$8)>0,"C"&sumproduct((TPTD!B$6:B$8=$B5),TPTD!$A$6:$A$8),"") -> C3 | H5: =if(sumproduct((TPTD!C$6:C$8=$B5),TPTD!$A$6:$A$8)>0,"C"&sumproduct((TPTD!C$6:C$8=$B5),TPTD!$A$6:$A$8),"") -> C1 | I5: =if(sumproduct((TPTD!D$6:D$8=$B5),TPTD!$A$6:$A$8)>0,"C"&sumproduct((TPTD!D$6:D$8=$B5),TPTD!$A$6:$A$8),"") -> C3 | J5: =if(sumproduct((TPTD!E$6:E$8=$B5),TPTD!$A$6:$A$8)>0,"C"&sumproduct((TPTD!E$6:E$8=$B5),TPTD!$A$6:$A$8),"") -> C1 | K5: =if(sumproduct((TPTD!F$6:F$8=$B5),TPTD!$A$6:$A$8)>0,"C"&sumproduct((TPTD!F$6:F$8=$B5),TPTD!$A$6:$A$8),"") -> C3 | M5: =if(sumproduct((TPTD!H$6:H$8=$B5),TPTD!$A$6:$A$8)>0,"C"&sumproduct((TPTD!H$6:H$8=$B5),TPTD!$A$6:$A$8),"") -> C3 | N5: =if(sumproduct((TPTD!I$6:I$8=$B5),TPTD!$A$6:$A$8)>0,"C"&sumproduct((TPTD!I$6:I$8=$B5),TPTD!$A$6:$A$8),"") -> C1 | O5: =if(sumproduct((TPTD!J$6:J$8=$B5),TPTD!$A$6:$A$8)>0,"C"&sumproduct((TPTD!J$6:J$8=$B5),TPTD!$A$6:$A$8),"") -> C3 | P5: =if(sumproduct((TPTD!K$6:K$8=$B5),TPTD!$A$6:$A$8)>0,"C"&sumproduct((TPTD!K$6:K$8=$B5),TPTD!$A$6:$A$8),"") -> C1 | Q5: =if(sumproduct((TPTD!L$6:L$8=$B5),TPTD!$A$6:$A$8)>0,"C"&sumproduct((TPTD!L$6:L$8=$B5),TPTD!$A$6:$A$8),"") -> C3 | R5: =if(sumproduct((TPTD!M$6:M$8=$B5),TPTD!$A$6:$A$8)>0,"C"&sumproduct((TPTD!M$6:M$8=$B5),TPTD!$A$6:$A$8),"") -> C1 | S5: =if(sumproduct((TPTD!N$6:N$8=$B5),TPTD!$A$6:$A$8)>0,"C"&sumproduct((TPTD!N$6:N$8=$B5),TPTD!$A$6:$A$8),"") -> C3 | U5: =if(sumproduct((TPTD!P$6:P$8=$B5),TPTD!$A$6:$A$8)>0,"C"&sumproduct((TPTD!P$6:P$8=$B5),TPTD!$A$6:$A$8),"") -> C1 | V5: =if(sumproduct((TPTD!Q$6:Q$8=$B5),TPTD!$A$6:$A$8)>0,"C"&sumproduct((TPTD!Q$6:Q$8=$B5),TPTD!$A$6:$A$8),"") -> C3 | W5: =if(sumproduct((TPTD!R$6:R$8=$B5),TPTD!$A$6:$A$8)>0,"C"&sumproduct((TPTD!R$6:R$8=$B5),TPTD!$A$6:$A$8),"") -> C1 | Z5: TD Anglais | AB5: Lundi 11h | AC5: G1
B6: 10 | D6: TP2 | E6: Mardi | F6: =B6&"h" -> 10h | G6: =if(sumproduct((TPTD!B$6:B$8=$B6),TPTD!$A$6:$A$8)>0,"C"&sumproduct((TPTD!B$6:B$8=$B6),TPTD!$A$6:$A$8),"") -> C1 | H6: =if(sumproduct((TPTD!C$6:C$8=$B6),TPTD!$A$6:$A$8)>0,"C"&sumproduct((TPTD!C$6:C$8=$B6),TPTD!$A$6:$A$8),"") -> C3 | I6: =if(sumproduct((TPTD!D$6:D$8=$B6),TPTD!$A$6:$A$8)>0,"C"&sumproduct((TPTD!D$6:D$8=$B6),TPTD!$A$6:$A$8),"") -> C1 | J6: =if(sumproduct((TPTD!E$6:E$8=$B6),TPTD!$A$6:$A$8)>0,"C"&sumproduct((TPTD!E$6:E$8=$B6),TPTD!$A$6:$A$8),"") -> C3 | K6: =if(sumproduct((TPTD!F$6:F$8=$B6),TPTD!$A$6:$A$8)>0,"C"&sumproduct((TPTD!F$6:F$8=$B6),TPTD!$A$6:$A$8),"") -> C1 | M6: =if(sumproduct((TPTD!H$6:H$8=$B6),TPTD!$A$6:$A$8)>0,"C"&sumproduct((TPTD!H$6:H$8=$B6),TPTD!$A$6:$A$8),"") -> C1 | N6: =if(sumproduct((TPTD!I$6:I$8=$B6),TPTD!$A$6:$A$8)>0,"C"&sumproduct((TPTD!I$6:I$8=$B6),TPTD!$A$6:$A$8),"") -> C3 | O6: =if(sumproduct((TPTD!J$6:J$8=$B6),TPTD!$A$6:$A$8)>0,"C"&sumproduct((TPTD!J$6:J$8=$B6),TPTD!$A$6:$A$8),"") -> C1 | P6: =if(sumproduct((TPTD!K$6:K$8=$B6),TPTD!$A$6:$A$8)>0,"C"&sumproduct((TPTD!K$6:K$8=$B6),TPTD!$A$6:$A$8),"") -> C3 | Q6: =if(sumproduct((TPTD!L$6:L$8=$B6),TPTD!$A$6:$A$8)>0,"C"&sumproduct((TPTD!L$6:L$8=$B6),TPTD!$A$6:$A$8),"") -> C1 | R6: =if(sumproduct((TPTD!M$6:M$8=$B6),TPTD!$A$6:$A$8)>0,"C"&sumproduct((TPTD!M$6:M$8=$B6),TPTD!$A$6:$A$8),"") -> C3 | S6: =if(sumproduct((TPTD!N$6:N$8=$B6),TPTD!$A$6:$A$8)>0,"C"&sumproduct((TPTD!N$6:N$8=$B6),TPTD!$A$6:$A$8),"") -> C1 | U6: =if(sumproduct((TPTD!P$6:P$8=$B6),TPTD!$A$6:$A$8)>0,"C"&sumproduct((TPTD!P$6:P$8=$B6),TPTD!$A$6:$A$8),"") -> C3 | V6: =if(sumproduct((TPTD!Q$6:Q$8=$B6),TPTD!$A$6:$A$8)>0,"C"&sumproduct((TPTD!Q$6:Q$8=$B6),TPTD!$A$6:$A$8),"") -> C1 | W6: =if(sumproduct((TPTD!R$6:R$8=$B6),TPTD!$A$6:$A$8)>0,"C"&sumproduct((TPTD!R$6:R$8=$B6),TPTD!$A$6:$A$8),"") -> C3 | AB6: Lundi 12h | AC6: G2
B7: 15 | D7: TP3 | E7: Mardi | F7: =B7&"h" -> 15h | G7: =if(sumproduct((TPTD!B$6:B$8=$B7),TPTD!$A$6:$A$8)>0,"C"&sumproduct((TPTD!B$6:B$8=$B7),TPTD!$A$6:$A$8),"") -> C2 | H7: =if(sumproduct((TPTD!C$6:C$8=$B7),TPTD!$A$6:$A$8)>0,"C"&sumproduct((TPTD!C$6:C$8=$B7),TPTD!$A$6:$A$8),"") -> C2 | I7: =if(sumproduct((TPTD!D$6:D$8=$B7),TPTD!$A$6:$A$8)>0,"C"&sumproduct((TPTD!D$6:D$8=$B7),TPTD!$A$6:$A$8),"") -> C2 | J7: =if(sumproduct((TPTD!E$6:E$8=$B7),TPTD!$A$6:$A$8)>0,"C"&sumproduct((TPTD!E$6:E$8=$B7),TPTD!$A$6:$A$8),"") -> C2 | K7: =if(sumproduct((TPTD!F$6:F$8=$B7),TPTD!$A$6:$A$8)>0,"C"&sumproduct((TPTD!F$6:F$8=$B7),TPTD!$A$6:$A$8),"") -> C2 | M7: =if(sumproduct((TPTD!H$6:H$8=$B7),TPTD!$A$6:$A$8)>0,"C"&sumproduct((TPTD!H$6:H$8=$B7),TPTD!$A$6:$A$8),"") -> C2 | N7: =if(sumproduct((TPTD!I$6:I$8=$B7),TPTD!$A$6:$A$8)>0,"C"&sumproduct((TPTD!I$6:I$8=$B7),TPTD!$A$6:$A$8),"") -> C2 | O7: =if(sumproduct((TPTD!J$6:J$8=$B7),TPTD!$A$6:$A$8)>0,"C"&sumproduct((TPTD!J$6:J$8=$B7),TPTD!$A$6:$A$8),"") -> C2 | P7: =if(sumproduct((TPTD!K$6:K$8=$B7),TPTD!$A$6:$A$8)>0,"C"&sumproduct((TPTD!K$6:K$8=$B7),TPTD!$A$6:$A$8),"") -> C2 | Q7: =if(sumproduct((TPTD!L$6:L$8=$B7),TPTD!$A$6:$A$8)>0,"C"&sumproduct((TPTD!L$6:L$8=$B7),TPTD!$A$6:$A$8),"") -> C2 | R7: =if(sumproduct((TPTD!M$6:M$8=$B7),TPTD!$A$6:$A$8)>0,"C"&sumproduct((TPTD!M$6:M$8=$B7),TPTD!$A$6:$A$8),"") -> C2 | S7: =if(sumproduct((TPTD!N$6:N$8=$B7),TPTD!$A$6:$A$8)>0,"C"&sumproduct((TPTD!N$6:N$8=$B7),TPTD!$A$6:$A$8),"") -> C2 | U7: =if(sumproduct((TPTD!P$6:P$8=$B7),TPTD!$A$6:$A$8)>0,"C"&sumproduct((TPTD!P$6:P$8=$B7),TPTD!$A$6:$A$8),"") -> C2 | V7: =if(sumproduct((TPTD!Q$6:Q$8=$B7),TPTD!$A$6:$A$8)>0,"C"&sumproduct((TPTD!Q$6:Q$8=$B7),TPTD!$A$6:$A$8),"") -> C2 | W7: =if(sumproduct((TPTD!R$6:R$8=$B7),TPTD!$A$6:$A$8)>0,"C"&sumproduct((TPTD!R$6:R$8=$B7),TPTD!$A$6:$A$8),"") -> C2 | Z7: TD Physique | AB7: Jeudi 10h | AC7: G1
D8: Info | AB8: Jeudi 11h | AC8: G2
B9: 15 | D9: TP1 | E9: Mardi | F9: =B9&"h" -> 15h | G9: =if(sumproduct((TPTD!B$10:B$12=$B9),TPTD!$A$10:$A$12)>0,"C"&sumproduct((TPTD!B$10:B$12=$B9),TPTD!$A$10:$A$12),"") -> C1 | H9: =if(sumproduct((TPTD!C$10:C$12=$B9),TPTD!$A$10:$A$12)>0,"C"&sumproduct((TPTD!C$10:C$12=$B9),TPTD!$A$10:$A$12),"") | I9: =if(sumproduct((TPTD!D$10:D$12=$B9),TPTD!$A$10:$A$12)>0,"C"&sumproduct((TPTD!D$10:D$12=$B9),TPTD!$A$10:$A$12),"") -> C3 | J9: =if(sumproduct((TPTD!E$10:E$12=$B9),TPTD!$A$10:$A$12)>0,"C"&sumproduct((TPTD!E$10:E$12=$B9),TPTD!$A$10:$A$12),"") | K9: =if(sumproduct((TPTD!F$10:F$12=$B9),TPTD!$A$10:$A$12)>0,"C"&sumproduct((TPTD!F$10:F$12=$B9),TPTD!$A$10:$A$12),"") -> C1 | M9: =if(sumproduct((TPTD!H$10:H$12=$B9),TPTD!$A$10:$A$12)>0,"C"&sumproduct((TPTD!H$10:H$12=$B9),TPTD!$A$10:$A$12),"") | N9: =if(sumproduct((TPTD!I$10:I$12=$B9),TPTD!$A$10:$A$12)>0,"C"&sumproduct((TPTD!I$10:I$12=$B9),TPTD!$A$10:$A$12),"") -> C1 | O9: =if(sumproduct((TPTD!J$10:J$12=$B9),TPTD!$A$10:$A$12)>0,"C"&sumproduct((TPTD!J$10:J$12=$B9),TPTD!$A$10:$A$12),"") | P9: =if(sumproduct((TPTD!K$10:K$12=$B9),TPTD!$A$10:$A$12)>0,"C"&sumproduct((TPTD!K$10:K$12=$B9),TPTD!$A$10:$A$12),"") -> C1 | Q9: =if(sumproduct((TPTD!L$10:L$12=$B9),TPTD!$A$10:$A$12)>0,"C"&sumproduct((TPTD!L$10:L$12=$B9),TPTD!$A$10:$A$12),"") | R9: =if(sumproduct((TPTD!M$10:M$12=$B9),TPTD!$A$10:$A$12)>0,"C"&sumproduct((TPTD!M$10:M$12=$B9),TPTD!$A$10:$A$12),"") -> C3 | S9: =if(sumproduct((TPTD!N$10:N$12=$B9),TPTD!$A$10:$A$12)>0,"C"&sumproduct((TPTD!N$10:N$12=$B9),TPTD!$A$10:$A$12),"") | U9: =if(sumproduct((TPTD!P$10:P$12=$B9),TPTD!$A$10:$A$12)>0,"C"&sumproduct((TPTD!P$10:P$12=$B9),TPTD!$A$10:$A$12),"") -> C1 | V9: =if(sumproduct((TPTD!Q$10:Q$12=$B9),TPTD!$A$10:$A$12)>0,"C"&sumproduct((TPTD!Q$10:Q$12=$B9),TPTD!$A$10:$A$12),"") | W9: =if(sumproduct((TPTD!R$10:R$12=$B9),TPTD!$A$10:$A$12)>0,"C"&sumproduct((TPTD!R$10:R$12=$B9),TPTD!$A$10:$A$12),"") | Z9: TD SI | AB9: Jeudi 10h | AC9: G2
B10: 17 | D10: TP2 | E10: Mardi | F10: =B10&"h" -> 17h | G10: =if(sumproduct((TPTD!B$10:B$12=$B10),TPTD!$A$10:$A$12)>0,"C"&sumproduct((TPTD!B$10:B$12=$B10),TPTD!$A$10:$A$12),"") -> C3 | H10: =if(sumproduct((TPTD!C$10:C$12=$B10),TPTD!$A$10:$A$12)>0,"C"&sumproduct((TPTD!C$10:C$12=$B10),TPTD!$A$10:$A$12),"") -> C2 | I10: =if(sumproduct((TPTD!D$10:D$12=$B10),TPTD!$A$10:$A$12)>0,"C"&sumproduct((TPTD!D$10:D$12=$B10),TPTD!$A$10:$A$12),"") -> C2 | J10: =if(sumproduct((TPTD!E$10:E$12=$B10),TPTD!$A$10:$A$12)>0,"C"&sumproduct((TPTD!E$10:E$12=$B10),TPTD!$A$10:$A$12),"") -> C1 | K10: =if(sumproduct((TPTD!F$10:F$12=$B10),TPTD!$A$10:$A$12)>0,"C"&sumproduct((TPTD!F$10:F$12=$B10),TPTD!$A$10:$A$12),"") -> C3 | M10: =if(sumproduct((TPTD!H$10:H$12=$B10),TPTD!$A$10:$A$12)>0,"C"&sumproduct((TPTD!H$10:H$12=$B10),TPTD!$A$10:$A$12),"") -> C2 | N10: =if(sumproduct((TPTD!I$10:I$12=$B10),TPTD!$A$10:$A$12)>0,"C"&sumproduct((TPTD!I$10:I$12=$B10),TPTD!$A$10:$A$12),"") -> C2 | O10: =if(sumproduct((TPTD!J$10:J$12=$B10),TPTD!$A$10:$A$12)>0,"C"&sumproduct((TPTD!J$10:J$12=$B10),TPTD!$A$10:$A$12),"") -> C3 | P10: =if(sumproduct((TPTD!K$10:K$12=$B10),TPTD!$A$10:$A$12)>0,"C"&sumproduct((TPTD!K$10:K$12=$B10),TPTD!$A$10:$A$12),"") -> C3 | Q10: =if(sumproduct((TPTD!L$10:L$12=$B10),TPTD!$A$10:$A$12)>0,"C"&sumproduct((TPTD!L$10:L$12=$B10),TPTD!$A$10:$A$12),"") -> C2 | R10: =if(sumproduct((TPTD!M$10:M$12=$B10),TPTD!$A$10:$A$12)>0,"C"&sumproduct((TPTD!M$10:M$12=$B10),TPTD!$A$10:$A$12),"") -> C2 | S10: =if(sumproduct((TPTD!N$10:N$12=$B10),TPTD!$A$10:$A$12)>0,"C"&sumproduct((TPTD!N$10:N$12=$B10),TPTD!$A$10:$A$12),"") -> C1 | U10: =if(sumproduct((TPTD!P$10:P$12=$B10),TPTD!$A$10:$A$12)>0,"C"&sumproduct((TPTD!P$10:P$12=$B10),TPTD!$A$10:$A$12),"") -> C2 | V10: =if(sumproduct((TPTD!Q$10:Q$12=$B10),TPTD!$A$10:$A$12)>0,"C"&sumproduct((TPTD!Q$10:Q$12=$B10),TPTD!$A$10:$A$12),"") -> C3 | W10: =if(sumproduct((TPTD!R$10:R$12=$B10),TPTD!$A$10:$A$12)>0,"C"&sumproduct((TPTD!R$10:R$12=$B10),TPTD!$A$10:$A$12),"") | AB10: Jeudi 11h | AC10: G1
D11: Chimie
B12: 15 | D12: TD | E12: Mercredi | F12: =B12&"h" -> 15h | G12: =if(sumproduct((TPTD!B$14:B$15=$B12),TPTD!$A$14:$A$15)>0,"G"&sumproduct((TPTD!B$14:B$15=$B12),TPTD!$A$14:$A$15),"") -> G1 | H12: =if(sumproduct((TPTD!C$14:C$15=$B12),TPTD!$A$14:$A$15)>0,"G"&sumproduct((TPTD!C$14:C$15=$B12),TPTD!$A$14:$A$15),"") -> G2 | I12: =if(sumproduct((TPTD!D$14:D$15=$B12),TPTD!$A$14:$A$15)>0,"G"&sumproduct((TPTD!D$14:D$15=$B12),TPTD!$A$14:$A$15),"") -> G1 | J12: =if(sumproduct((TPTD!E$14:E$15=$B12),TPTD!$A$14:$A$15)>0,"G"&sumproduct((TPTD!E$14:E$15=$B12),TPTD!$A$14:$A$15),"") -> G2 | K12: =if(sumproduct((TPTD!F$14:F$15=$B12),TPTD!$A$14:$A$15)>0,"G"&sumproduct((TPTD!F$14:F$15=$B12),TPTD!$A$14:$A$15),"") | M12: =if(sumproduct((TPTD!H$14:H$15=$B12),TPTD!$A$14:$A$15)>0,"G"&sumproduct((TPTD!H$14:H$15=$B12),TPTD!$A$14:$A$15),"") -> G1 | N12: =if(sumproduct((TPTD!I$14:I$15=$B12),TPTD!$A$14:$A$15)>0,"G"&sumproduct((TPTD!I$14:I$15=$B12),TPTD!$A$14:$A$15),"") | O12: =if(sumproduct((TPTD!J$14:J$15=$B12),TPTD!$A$14:$A$15)>0,"G"&sumproduct((TPTD!J$14:J$15=$B12),TPTD!$A$14:$A$15),"") -> G2 | P12: =if(sumproduct((TPTD!K$14:K$15=$B12),TPTD!$A$14:$A$15)>0,"G"&sumproduct((TPTD!K$14:K$15=$B12),TPTD!$A$14:$A$15),"") -> G1 | Q12: =if(sumproduct((TPTD!L$14:L$15=$B12),TPTD!$A$14:$A$15)>0,"G"&sumproduct((TPTD!L$14:L$15=$B12),TPTD!$A$14:$A$15),"") -> G2 | R12: =if(sumproduct((TPTD!M$14:M$15=$B12),TPTD!$A$14:$A$15)>0,"G"&sumproduct((TPTD!M$14:M$15=$B12),TPTD!$A$14:$A$15),"") -> G1 | S12: =if(sumproduct((TPTD!N$14:N$15=$B12),TPTD!$A$14:$A$15)>0,"G"&sumproduct((TPTD!N$14:N$15=$B12),TPTD!$A$14:$A$15),"") -> G2 | U12: =if(sumproduct((TPTD!P$14:P$15=$B12),TPTD!$A$14:$A$15)>0,"G"&sumproduct((TPTD!P$14:P$15=$B12),TPTD!$A$14:$A$15),"") -> G1 | V12: =if(sumproduct((TPTD!Q$14:Q$15=$B12),TPTD!$A$14:$A$15)>0,"G"&sumproduct((TPTD!Q$14:Q$15=$B12),TPTD!$A$14:$A$15),"") -> G2 | W12: =if(sumproduct((TPTD!R$14:R$15=$B12),TPTD!$A$14:$A$15)>0,"G"&sumproduct((TPTD!R$14:R$15=$B12),TPTD!$A$14:$A$15),"") -> G1 | Z12: Groupes | AB12: Trinômes
D13: Physique | Z13: ="C1"&'Trinômes'!R18 -> C1 | AB13: ='Trinômes'!Q18 -> 1 – 2 – 3 – 4 – 5 – 6
B14: 8 | D14: TP1 | E14: Mardi | F14: =B14&"h" -> 8h | G14: =if(sumproduct((TPTD!B$3:B$4=$B14),TPTD!$A$3:$A$4)>0,"G"&sumproduct((TPTD!B$3:B$4=$B14),TPTD!$A$3:$A$4),"") -> G1 | H14: =if(sumproduct((TPTD!C$3:C$4=$B14),TPTD!$A$3:$A$4)>0,"G"&sumproduct((TPTD!C$3:C$4=$B14),TPTD!$A$3:$A$4),"") -> G2 | I14: =if(sumproduct((TPTD!D$3:D$4=$B14),TPTD!$A$3:$A$4)>0,"G"&sumproduct((TPTD!D$3:D$4=$B14),TPTD!$A$3:$A$4),"") -> G1 | J14: =if(sumproduct((TPTD!E$3:E$4=$B14),TPTD!$A$3:$A$4)>0,"G"&sumproduct((TPTD!E$3:E$4=$B14),TPTD!$A$3:$A$4),"") -> G2 | K14: =if(sumproduct((TPTD!F$3:F$4=$B14),TPTD!$A$3:$A$4)>0,"G"&sumproduct((TPTD!F$3:F$4=$B14),TPTD!$A$3:$A$4),"") -> G1 | M14: =if(sumproduct((TPTD!H$3:H$4=$B14),TPTD!$A$3:$A$4)>0,"G"&sumproduct((TPTD!H$3:H$4=$B14),TPTD!$A$3:$A$4),"") -> G1 | N14: =if(sumproduct((TPTD!I$3:I$4=$B14),TPTD!$A$3:$A$4)>0,"G"&sumproduct((TPTD!I$3:I$4=$B14),TPTD!$A$3:$A$4),"") -> G2 | O14: =if(sumproduct((TPTD!J$3:J$4=$B14),TPTD!$A$3:$A$4)>0,"G"&sumproduct((TPTD!J$3:J$4=$B14),TPTD!$A$3:$A$4),"") -> G1 | P14: =if(sumproduct((TPTD!K$3:K$4=$B14),TPTD!$A$3:$A$4)>0,"G"&sumproduct((TPTD!K$3:K$4=$B14),TPTD!$A$3:$A$4),"") -> G2 | Q14: =if(sumproduct((TPTD!L$3:L$4=$B14),TPTD!$A$3:$A$4)>0,"G"&sumproduct((TPTD!L$3:L$4=$B14),TPTD!$A$3:$A$4),"") -> G1 | R14: =if(sumproduct((TPTD!M$3:M$4=$B14),TPTD!$A$3:$A$4)>0,"G"&sumproduct((TPTD!M$3:M$4=$B14),TPTD!$A$3:$A$4),"") -> G2 | S14: =if(sumproduct((TPTD!N$3:N$4=$B14),TPTD!$A$3:$A$4)>0,"G"&sumproduct((TPTD!N$3:N$4=$B14),TPTD!$A$3:$A$4),"") -> G1 | U14: =if(sumproduct((TPTD!P$3:P$4=$B14),TPTD!$A$3:$A$4)>0,"G"&sumproduct((TPTD!P$3:P$4=$B14),TPTD!$A$3:$A$4),"") -> G2 | V14: =if(sumproduct((TPTD!Q$3:Q$4=$B14),TPTD!$A$3:$A$4)>0,"G"&sumproduct((TPTD!Q$3:Q$4=$B14),TPTD!$A$3:$A$4),"") -> G1 | W14: =if(sumproduct((TPTD!R$3:R$4=$B14),TPTD!$A$3:$A$4)>0,"G"&sumproduct((TPTD!R$3:R$4=$B14),TPTD!$A$3:$A$4),"") -> G2 | Z14: ="C2"&'Trinômes'!U18 -> C2 | AB14: ='Trinômes'!T18 -> 7 – 8 – 9 – 10 – 11
B15: 10 | D15: TP2 | E15: Mardi | F15: =B15&"h" -> 10h | G15: =if(sumproduct((TPTD!B$3:B$4=$B15),TPTD!$A$3:$A$4)>0,"G"&sumproduct((TPTD!B$3:B$4=$B15),TPTD!$A$3:$A$4),"") -> G2 | H15: =if(sumproduct((TPTD!C$3:C$4=$B15),TPTD!$A$3:$A$4)>0,"G"&sumproduct((TPTD!C$3:C$4=$B15),TPTD!$A$3:$A$4),"") -> G1 | I15: =if(sumproduct((TPTD!D$3:D$4=$B15),TPTD!$A$3:$A$4)>0,"G"&sumproduct((TPTD!D$3:D$4=$B15),TPTD!$A$3:$A$4),"") -> G2 | J15: =if(sumproduct((TPTD!E$3:E$4=$B15),TPTD!$A$3:$A$4)>0,"G"&sumproduct((TPTD!E$3:E$4=$B15),TPTD!$A$3:$A$4),"") -> G1 | K15: =if(sumproduct((TPTD!F$3:F$4=$B15),TPTD!$A$3:$A$4)>0,"G"&sumproduct((TPTD!F$3:F$4=$B15),TPTD!$A$3:$A$4),"") -> G2 | M15: =if(sumproduct((TPTD!H$3:H$4=$B15),TPTD!$A$3:$A$4)>0,"G"&sumproduct((TPTD!H$3:H$4=$B15),TPTD!$A$3:$A$4),"") -> G2 | N15: =if(sumproduct((TPTD!I$3:I$4=$B15),TPTD!$A$3:$A$4)>0,"G"&sumproduct((TPTD!I$3:I$4=$B15),TPTD!$A$3:$A$4),"") -> G1 | O15: =if(sumproduct((TPTD!J$3:J$4=$B15),TPTD!$A$3:$A$4)>0,"G"&sumproduct((TPTD!J$3:J$4=$B15),TPTD!$A$3:$A$4),"") -> G2 | P15: =if(sumproduct((TPTD!K$3:K$4=$B15),TPTD!$A$3:$A$4)>0,"G"&sumproduct((TPTD!K$3:K$4=$B15),TPTD!$A$3:$A$4),"") -> G1 | Q15: =if(sumproduct((TPTD!L$3:L$4=$B15),TPTD!$A$3:$A$4)>0,"G"&sumproduct((TPTD!L$3:L$4=$B15),TPTD!$A$3:$A$4),"") -> G2 | R15: =if(sumproduct((TPTD!M$3:M$4=$B15),TPTD!$A$3:$A$4)>0,"G"&sumproduct((TPTD!M$3:M$4=$B15),TPTD!$A$3:$A$4),"") -> G1 | S15: =if(sumproduct((TPTD!N$3:N$4=$B15),TPTD!$A$3:$A$4)>0,"G"&sumproduct((TPTD!N$3:N$4=$B15),TPTD!$A$3:$A$4),"") -> G2 | U15: =if(sumproduct((TPTD!P$3:P$4=$B15),TPTD!$A$3:$A$4)>0,"G"&sumproduct((TPTD!P$3:P$4=$B15),TPTD!$A$3:$A$4),"") -> G1 | V15: =if(sumproduct((TPTD!Q$3:Q$4=$B15),TPTD!$A$3:$A$4)>0,"G"&sumproduct((TPTD!Q$3:Q$4=$B15),TPTD!$A$3:$A$4),"") -> G2 | W15: =if(sumproduct((TPTD!R$3:R$4=$B15),TPTD!$A$3:$A$4)>0,"G"&sumproduct((TPTD!R$3:R$4=$B15),TPTD!$A$3:$A$4),"") -> G1 | Z15: ="C3"&'Trinômes'!X18 -> C3 – LV2 | AB15: ='Trinômes'!W18 -> 12 – 13 – 14 – 15 – 16
Z16: ="G1"&'Trinômes'!L18 -> G1 | AB16: ='Trinômes'!K18 -> 1 – 2 – 3 – 4 – 5 – 6 – 7 – 8
C17: Colleur | D17: Jour | E17: Heure | F17: Salle | Z17: ="G2"&'Trinômes'!O18 -> G2 – LV2 | AB17: ='Trinômes'!N18 -> 9 – 10 – 11 – 12 – 13 – 14 – 15 – 16
C18: =A19 -> Mathématiques
A19: ='Créneaux'!I2 -> Mathématiques | B19: ='Créneaux'!J2 -> 1 | C19: ='Créneaux'!K2 -> M. Villéger | D19: =switch('Créneaux'!L2,0,"Lundi",1,"Mardi",2,"Mercredi",3,"Jeudi",4,"Vendredi") -> Mercredi | E19: ='Créneaux'!M2&"h" -> 15h | F19: ='Créneaux'!N2 -> Prépa 35 | G19: =if(sumproduct((Colles!$A$2:$A$97=$A19),(Colles!C$2:C$97=$B19),(Colles!$B$2:$B$97))>0,sumproduct((Colles!$A$2:$A$97=$A19),(Colles!C$2:C$97=$B19),(Colles!$B$2:$B$97)),"") | H19: =if(sumproduct((Colles!$A$2:$A$97=$A19),(Colles!D$2:D$97=$B19),(Colles!$B$2:$B$97))>0,sumproduct((Colles!$A$2:$A$97=$A19),(Colles!D$2:D$97=$B19),(Colles!$B$2:$B$97)),"") -> 1 | I19: =if(sumproduct((Colles!$A$2:$A$97=$A19),(Colles!E$2:E$97=$B19),(Colles!$B$2:$B$97))>0,sumproduct((Colles!$A$2:$A$97=$A19),(Colles!E$2:E$97=$B19),(Colles!$B$2:$B$97)),"") -> 14 | J19: =if(sumproduct((Colles!$A$2:$A$97=$A19),(Colles!F$2:F$97=$B19),(Colles!$B$2:$B$97))>0,sumproduct((Colles!$A$2:$A$97=$A19),(Colles!F$2:F$97=$B19),(Colles!$B$2:$B$97)),"") -> 7 | K19: =if(sumproduct((Colles!$A$2:$A$97=$A19),(Colles!G$2:G$97=$B19),(Colles!$B$2:$B$97))>0,sumproduct((Colles!$A$2:$A$97=$A19),(Colles!G$2:G$97=$B19),(Colles!$B$2:$B$97)),"") -> 12 | M19: =if(sumproduct((Colles!$A$2:$A$97=$A19),(Colles!I$2:I$97=$B19),(Colles!$B$2:$B$97))>0,sumproduct((Colles!$A$2:$A$97=$A19),(Colles!I$2:I$97=$B19),(Colles!$B$2:$B$97)),"") -> 11 | N19: =if(sumproduct((Colles!$A$2:$A$97=$A19),(Colles!J$2:J$97=$B19),(Colles!$B$2:$B$97))>0,sumproduct((Colles!$A$2:$A$97=$A19),(Colles!J$2:J$97=$B19),(Colles!$B$2:$B$97)),"") -> 10 | O19: =if(sumproduct((Colles!$A$2:$A$97=$A19),(Colles!K$2:K$97=$B19),(Colles!$B$2:$B$97))>0,sumproduct((Colles!$A$2:$A$97=$A19),(Colles!K$2:K$97=$B19),(Colles!$B$2:$B$97)),"") -> 7 | P19: =if(sumproduct((Colles!$A$2:$A$97=$A19),(Colles!L$2:L$97=$B19),(Colles!$B$2:$B$97))>0,sumproduct((Colles!$A$2:$A$97=$A19),(Colles!L$2:L$97=$B19),(Colles!$B$2:$B$97)),"") -> 16 | Q19: =if(sumproduct((Colles!$A$2:$A$97=$A19),(Colles!M$2:M$97=$B19),(Colles!$B$2:$B$97))>0,sumproduct((Colles!$A$2:$A$97=$A19),(Colles!M$2:M$97=$B19),(Colles!$B$2:$B$97)),"") -> 1 | R19: =if(sumproduct((Colles!$A$2:$A$97=$A19),(Colles!N$2:N$97=$B19),(Colles!$B$2:$B$97))>0,sumproduct((Colles!$A$2:$A$97=$A19),(Colles!N$2:N$97=$B19),(Colles!$B$2:$B$97)),"") -> 14 | S19: =if(sumproduct((Colles!$A$2:$A$97=$A19),(Colles!O$2:O$97=$B19),(Colles!$B$2:$B$97))>0,sumproduct((Colles!$A$2:$A$97=$A19),(Colles!O$2:O$97=$B19),(Colles!$B$2:$B$97)),"") -> 3 | U19: =if(sumproduct((Colles!$A$2:$A$97=$A19),(Colles!Q$2:Q$97=$B19),(Colles!$B$2:$B$97))>0,sumproduct((Colles!$A$2:$A$97=$A19),(Colles!Q$2:Q$97=$B19),(Colles!$B$2:$B$97)),"") | V19: =if(sumproduct((Colles!$A$2:$A$97=$A19),(Colles!R$2:R$97=$B19),(Colles!$B$2:$B$97))>0,sumproduct((Colles!$A$2:$A$97=$A19),(Colles!R$2:R$97=$B19),(Colles!$B$2:$B$97)),"") -> 4 | W19: =if(sumproduct((Colles!$A$2:$A$97=$A19),(Colles!S$2:S$97=$B19),(Colles!$B$2:$B$97))>0,sumproduct((Colles!$A$2:$A$97=$A19),(Colles!S$2:S$97=$B19),(Colles!$B$2:$B$97)),"") -> 15 | Z19: Trinômes
A20: ='Créneaux'!I3 -> Mathématiques | B20: ='Créneaux'!J3 -> 2 | C20: ='Créneaux'!K3 -> M. Villéger | D20: =switch('Créneaux'!L3,0,"Lundi",1,"Mardi",2,"Mercredi",3,"Jeudi",4,"Vendredi") -> Mercredi | E20: ='Créneaux'!M3&"h" -> 16h | F20: ='Créneaux'!N3 -> Prépa 35 | G20: =if(sumproduct((Colles!$A$2:$A$97=$A20),(Colles!C$2:C$97=$B20),(Colles!$B$2:$B$97))>0,sumproduct((Colles!$A$2:$A$97=$A20),(Colles!C$2:C$97=$B20),(Colles!$B$2:$B$97)),"") | H20: =if(sumproduct((Colles!$A$2:$A$97=$A20),(Colles!D$2:D$97=$B20),(Colles!$B$2:$B$97))>0,sumproduct((Colles!$A$2:$A$97=$A20),(Colles!D$2:D$97=$B20),(Colles!$B$2:$B$97)),"") -> 15 | I20: =if(sumproduct((Colles!$A$2:$A$97=$A20),(Colles!E$2:E$97=$B20),(Colles!$B$2:$B$97))>0,sumproduct((Colles!$A$2:$A$97=$A20),(Colles!E$2:E$97=$B20),(Colles!$B$2:$B$97)),"") -> 4 | J20: =if(sumproduct((Colles!$A$2:$A$97=$A20),(Colles!F$2:F$97=$B20),(Colles!$B$2:$B$97))>0,sumproduct((Colles!$A$2:$A$97=$A20),(Colles!F$2:F$97=$B20),(Colles!$B$2:$B$97)),"") -> 13 | K20: =if(sumproduct((Colles!$A$2:$A$97=$A20),(Colles!G$2:G$97=$B20),(Colles!$B$2:$B$97))>0,sumproduct((Colles!$A$2:$A$97=$A20),(Colles!G$2:G$97=$B20),(Colles!$B$2:$B$97)),"") -> 6 | M20: =if(sumproduct((Colles!$A$2:$A$97=$A20),(Colles!I$2:I$97=$B20),(Colles!$B$2:$B$97))>0,sumproduct((Colles!$A$2:$A$97=$A20),(Colles!I$2:I$97=$B20),(Colles!$B$2:$B$97)),"") -> 5 | N20: =if(sumproduct((Colles!$A$2:$A$97=$A20),(Colles!J$2:J$97=$B20),(Colles!$B$2:$B$97))>0,sumproduct((Colles!$A$2:$A$97=$A20),(Colles!J$2:J$97=$B20),(Colles!$B$2:$B$97)),"") -> 8 | O20: =if(sumproduct((Colles!$A$2:$A$97=$A20),(Colles!K$2:K$97=$B20),(Colles!$B$2:$B$97))>0,sumproduct((Colles!$A$2:$A$97=$A20),(Colles!K$2:K$97=$B20),(Colles!$B$2:$B$97)),"") -> 9 | P20: =if(sumproduct((Colles!$A$2:$A$97=$A20),(Colles!L$2:L$97=$B20),(Colles!$B$2:$B$97))>0,sumproduct((Colles!$A$2:$A$97=$A20),(Colles!L$2:L$97=$B20),(Colles!$B$2:$B$97)),"") -> 2 | Q20: =if(sumproduct((Colles!$A$2:$A$97=$A20),(Colles!M$2:M$97=$B20),(Colles!$B$2:$B$97))>0,sumproduct((Colles!$A$2:$A$97=$A20),(Colles!M$2:M$97=$B20),(Colles!$B$2:$B$97)),"") -> 15 | R20: =if(sumproduct((Colles!$A$2:$A$97=$A20),(Colles!N$2:N$97=$B20),(Colles!$B$2:$B$97))>0,sumproduct((Colles!$A$2:$A$97=$A20),(Colles!N$2:N$97=$B20),(Colles!$B$2:$B$97)),"") -> 4 | S20: =if(sumproduct((Colles!$A$2:$A$97=$A20),(Colles!O$2:O$97=$B20),(Colles!$B$2:$B$97))>0,sumproduct((Colles!$A$2:$A$97=$A20),(Colles!O$2:O$97=$B20),(Colles!$B$2:$B$97)),"") -> 9 | U20: =if(sumproduct((Colles!$A$2:$A$97=$A20),(Colles!Q$2:Q$97=$B20),(Colles!$B$2:$B$97))>0,sumproduct((Colles!$A$2:$A$97=$A20),(Colles!Q$2:Q$97=$B20),(Colles!$B$2:$B$97)),"") | V20: =if(sumproduct((Colles!$A$2:$A$97=$A20),(Colles!R$2:R$97=$B20),(Colles!$B$2:$B$97))>0,sumproduct((Colles!$A$2:$A$97=$A20),(Colles!R$2:R$97=$B20),(Colles!$B$2:$B$97)),"") -> 16 | W20: =if(sumproduct((Colles!$A$2:$A$97=$A20),(Colles!S$2:S$97=$B20),(Colles!$B$2:$B$97))>0,sumproduct((Colles!$A$2:$A$97=$A20),(Colles!S$2:S$97=$B20),(Colles!$B$2:$B$97)),"") -> 1
A21: ='Créneaux'!I4 -> Mathématiques | B21: ='Créneaux'!J4 -> 3 | C21: ='Créneaux'!K4 -> Mme Gil | D21: =switch('Créneaux'!L4,0,"Lundi",1,"Mardi",2,"Mercredi",3,"Jeudi",4,"Vendredi") -> Mercredi | E21: ='Créneaux'!M4&"h" -> 15h | F21: ='Créneaux'!N4 -> Prépa 22 | G21: =if(sumproduct((Colles!$A$2:$A$97=$A21),(Colles!C$2:C$97=$B21),(Colles!$B$2:$B$97))>0,sumproduct((Colles!$A$2:$A$97=$A21),(Colles!C$2:C$97=$B21),(Colles!$B$2:$B$97)),"") | H21: =if(sumproduct((Colles!$A$2:$A$97=$A21),(Colles!D$2:D$97=$B21),(Colles!$B$2:$B$97))>0,sumproduct((Colles!$A$2:$A$97=$A21),(Colles!D$2:D$97=$B21),(Colles!$B$2:$B$97)),"") -> 3 | I21: =if(sumproduct((Colles!$A$2:$A$97=$A21),(Colles!E$2:E$97=$B21),(Colles!$B$2:$B$97))>0,sumproduct((Colles!$A$2:$A$97=$A21),(Colles!E$2:E$97=$B21),(Colles!$B$2:$B$97)),"") -> 16 | J21: =if(sumproduct((Colles!$A$2:$A$97=$A21),(Colles!F$2:F$97=$B21),(Colles!$B$2:$B$97))>0,sumproduct((Colles!$A$2:$A$97=$A21),(Colles!F$2:F$97=$B21),(Colles!$B$2:$B$97)),"") -> 5 | K21: =if(sumproduct((Colles!$A$2:$A$97=$A21),(Colles!G$2:G$97=$B21),(Colles!$B$2:$B$97))>0,sumproduct((Colles!$A$2:$A$97=$A21),(Colles!G$2:G$97=$B21),(Colles!$B$2:$B$97)),"") -> 10 | M21: =if(sumproduct((Colles!$A$2:$A$97=$A21),(Colles!I$2:I$97=$B21),(Colles!$B$2:$B$97))>0,sumproduct((Colles!$A$2:$A$97=$A21),(Colles!I$2:I$97=$B21),(Colles!$B$2:$B$97)),"") -> 15 | N21: =if(sumproduct((Colles!$A$2:$A$97=$A21),(Colles!J$2:J$97=$B21),(Colles!$B$2:$B$97))>0,sumproduct((Colles!$A$2:$A$97=$A21),(Colles!J$2:J$97=$B21),(Colles!$B$2:$B$97)),"") -> 16 | O21: =if(sumproduct((Colles!$A$2:$A$97=$A21),(Colles!K$2:K$97=$B21),(Colles!$B$2:$B$97))>0,sumproduct((Colles!$A$2:$A$97=$A21),(Colles!K$2:K$97=$B21),(Colles!$B$2:$B$97)),"") -> 5 | P21: =if(sumproduct((Colles!$A$2:$A$97=$A21),(Colles!L$2:L$97=$B21),(Colles!$B$2:$B$97))>0,sumproduct((Colles!$A$2:$A$97=$A21),(Colles!L$2:L$97=$B21),(Colles!$B$2:$B$97)),"") -> 14 | Q21: =if(sumproduct((Colles!$A$2:$A$97=$A21),(Colles!M$2:M$97=$B21),(Colles!$B$2:$B$97))>0,sumproduct((Colles!$A$2:$A$97=$A21),(Colles!M$2:M$97=$B21),(Colles!$B$2:$B$97)),"") -> 3 | R21: =if(sumproduct((Colles!$A$2:$A$97=$A21),(Colles!N$2:N$97=$B21),(Colles!$B$2:$B$97))>0,sumproduct((Colles!$A$2:$A$97=$A21),(Colles!N$2:N$97=$B21),(Colles!$B$2:$B$97)),"") -> 10 | S21: =if(sumproduct((Colles!$A$2:$A$97=$A21),(Colles!O$2:O$97=$B21),(Colles!$B$2:$B$97))>0,sumproduct((Colles!$A$2:$A$97=$A21),(Colles!O$2:O$97=$B21),(Colles!$B$2:$B$97)),"") -> 7 | U21: =if(sumproduct((Colles!$A$2:$A$97=$A21),(Colles!Q$2:Q$97=$B21),(Colles!$B$2:$B$97))>0,sumproduct((Colles!$A$2:$A$97=$A21),(Colles!Q$2:Q$97=$B21),(Colles!$B$2:$B$97)),"") | V21: =if(sumproduct((Colles!$A$2:$A$97=$A21),(Colles!R$2:R$97=$B21),(Colles!$B$2:$B$97))>0,sumproduct((Colles!$A$2:$A$97=$A21),(Colles!R$2:R$97=$B21),(Colles!$B$2:$B$97)),"") -> 2 | W21: =if(sumproduct((Colles!$A$2:$A$97=$A21),(Colles!S$2:S$97=$B21),(Colles!$B$2:$B$97))>0,sumproduct((Colles!$A$2:$A$97=$A21),(Colles!S$2:S$97=$B21),(Colles!$B$2:$B$97)),"") -> 9 | Y21: 1 | Z21: =Y21&IF(SUMPRODUCT('Trinômes'!$A$2:$A$48=Z22,'Trinômes'!$D$2:$D$48<>0)+SUMPRODUCT('Trinômes'!$A$2:$A$48=Z23,'Trinômes'!$D$2:$D$48<>0)+SUMPRODUCT('Trinômes'!$A$2:$A$48=Z24,'Trinômes'!$D$2:$D$48<>0)>0," – LV2","") -> 1 | AA21: =Y21+1 -> 2 | AB21: =AA21&IF(SUMPRODUCT('Trinômes'!$A$2:$A$48=AB22,'Trinômes'!$D$2:$D$48<>0)+SUMPRODUCT('Trinômes'!$A$2:$A$48=AB23,'Trinômes'!$D$2:$D$48<>0)+SUMPRODUCT('Trinômes'!$A$2:$A$48=AB24,'Trinômes'!$D$2:$D$48<>0)>0," – LV2","") -> 2
A22: ='Créneaux'!I5 -> Mathématiques | B22: ='Créneaux'!J5 -> 4 | C22: ='Créneaux'!K5 -> M. Franch | D22: =switch('Créneaux'!L5,0,"Lundi",1,"Mardi",2,"Mercredi",3,"Jeudi",4,"Vendredi") -> Mercredi | E22: ='Créneaux'!M5&"h" -> 17h | F22: ='Créneaux'!N5 -> Prépa 23 | G22: =if(sumproduct((Colles!$A$2:$A$97=$A22),(Colles!C$2:C$97=$B22),(Colles!$B$2:$B$97))>0,sumproduct((Colles!$A$2:$A$97=$A22),(Colles!C$2:C$97=$B22),(Colles!$B$2:$B$97)),"") | H22: =if(sumproduct((Colles!$A$2:$A$97=$A22),(Colles!D$2:D$97=$B22),(Colles!$B$2:$B$97))>0,sumproduct((Colles!$A$2:$A$97=$A22),(Colles!D$2:D$97=$B22),(Colles!$B$2:$B$97)),"") -> 11 | I22: =if(sumproduct((Colles!$A$2:$A$97=$A22),(Colles!E$2:E$97=$B22),(Colles!$B$2:$B$97))>0,sumproduct((Colles!$A$2:$A$97=$A22),(Colles!E$2:E$97=$B22),(Colles!$B$2:$B$97)),"") -> 6 | J22: =if(sumproduct((Colles!$A$2:$A$97=$A22),(Colles!F$2:F$97=$B22),(Colles!$B$2:$B$97))>0,sumproduct((Colles!$A$2:$A$97=$A22),(Colles!F$2:F$97=$B22),(Colles!$B$2:$B$97)),"") -> 9 | K22: =if(sumproduct((Colles!$A$2:$A$97=$A22),(Colles!G$2:G$97=$B22),(Colles!$B$2:$B$97))>0,sumproduct((Colles!$A$2:$A$97=$A22),(Colles!G$2:G$97=$B22),(Colles!$B$2:$B$97)),"") -> 8 | M22: =if(sumproduct((Colles!$A$2:$A$97=$A22),(Colles!I$2:I$97=$B22),(Colles!$B$2:$B$97))>0,sumproduct((Colles!$A$2:$A$97=$A22),(Colles!I$2:I$97=$B22),(Colles!$B$2:$B$97)),"") -> 13 | N22: =if(sumproduct((Colles!$A$2:$A$97=$A22),(Colles!J$2:J$97=$B22),(Colles!$B$2:$B$97))>0,sumproduct((Colles!$A$2:$A$97=$A22),(Colles!J$2:J$97=$B22),(Colles!$B$2:$B$97)),"") -> 2 | O22: =if(sumproduct((Colles!$A$2:$A$97=$A22),(Colles!K$2:K$97=$B22),(Colles!$B$2:$B$97))>0,sumproduct((Colles!$A$2:$A$97=$A22),(Colles!K$2:K$97=$B22),(Colles!$B$2:$B$97)),"") -> 13 | P22: =if(sumproduct((Colles!$A$2:$A$97=$A22),(Colles!L$2:L$97=$B22),(Colles!$B$2:$B$97))>0,sumproduct((Colles!$A$2:$A$97=$A22),(Colles!L$2:L$97=$B22),(Colles!$B$2:$B$97)),"") -> 4 | Q22: =if(sumproduct((Colles!$A$2:$A$97=$A22),(Colles!M$2:M$97=$B22),(Colles!$B$2:$B$97))>0,sumproduct((Colles!$A$2:$A$97=$A22),(Colles!M$2:M$97=$B22),(Colles!$B$2:$B$97)),"") -> 11 | R22: =if(sumproduct((Colles!$A$2:$A$97=$A22),(Colles!N$2:N$97=$B22),(Colles!$B$2:$B$97))>0,sumproduct((Colles!$A$2:$A$97=$A22),(Colles!N$2:N$97=$B22),(Colles!$B$2:$B$97)),"") -> 6 | S22: =if(sumproduct((Colles!$A$2:$A$97=$A22),(Colles!O$2:O$97=$B22),(Colles!$B$2:$B$97))>0,sumproduct((Colles!$A$2:$A$97=$A22),(Colles!O$2:O$97=$B22),(Colles!$B$2:$B$97)),"") -> 13 | U22: =if(sumproduct((Colles!$A$2:$A$97=$A22),(Colles!Q$2:Q$97=$B22),(Colles!$B$2:$B$97))>0,sumproduct((Colles!$A$2:$A$97=$A22),(Colles!Q$2:Q$97=$B22),(Colles!$B$2:$B$97)),"") | V22: =if(sumproduct((Colles!$A$2:$A$97=$A22),(Colles!R$2:R$97=$B22),(Colles!$B$2:$B$97))>0,sumproduct((Colles!$A$2:$A$97=$A22),(Colles!R$2:R$97=$B22),(Colles!$B$2:$B$97)),"") -> 10 | W22: =if(sumproduct((Colles!$A$2:$A$97=$A22),(Colles!S$2:S$97=$B22),(Colles!$B$2:$B$97))>0,sumproduct((Colles!$A$2:$A$97=$A22),(Colles!S$2:S$97=$B22),(Colles!$B$2:$B$97)),"") -> 3 | Y22: =Y21 -> 1 | Z22: {=IF(ISERROR(ADDRESS(SUMPRODUCT('Trinômes'!$B$2:$B$48=Y22,'Trinômes'!$C$2:$C$48=COUNTIF(Y$21:Y22,"="&Y22)-1 ,ROW('Trinômes'!$A$2:$A$48)),COLUMN('Trinômes'!$A$1)-COLUMN('Trinômes'!$A$1)+1)),"",indirect("Trinômes!"&ADDRESS(SUMPRODUCT('Trinômes'!$B$2:$B$48=Y22,'Trinômes'!$C$2:$C$48=COUNTIF(Y$21:Y22,"="&Y22)-1 ,ROW('Trinômes'!$A$2:$A$48)),COLUMN('Trinômes'!$A$1)-COLUMN('Trinômes'!$A$1)+1)))} -> ALDEHUELO--LESINSKI Axel | AA22: =AA21 -> 2 | AB22: {=IF(ISERROR(ADDRESS(SUMPRODUCT('Trinômes'!$B$2:$B$48=AA22,'Trinômes'!$C$2:$C$48=COUNTIF(AA$21:AA22,"="&AA22)-1 ,ROW('Trinômes'!$A$2:$A$48)),COLUMN('Trinômes'!$A$1)-COLUMN('Trinômes'!$A$1)+1)),"",indirect("Trinômes!"&ADDRESS(SUMPRODUCT('Trinômes'!$B$2:$B$48=AA22,'Trinômes'!$C$2:$C$48=COUNTIF(AA$21:AA22,"="&AA22)-1 ,ROW('Trinômes'!$A$2:$A$48)),COLUMN('Trinômes'!$A$1)-COLUMN('Trinômes'!$A$1)+1)))} -> BONNEVAL Lucie
A23: ='Créneaux'!I6 -> Mathématiques | B23: ='Créneaux'!J6 -> 5 | C23: ='Créneaux'!K6 -> M. Ghiberti | D23: =switch('Créneaux'!L6,0,"Lundi",1,"Mardi",2,"Mercredi",3,"Jeudi",4,"Vendredi") -> Lundi | E23: ='Créneaux'!M6&"h" -> 17h | F23: ='Créneaux'!N6 -> K22 | G23: =if(sumproduct((Colles!$A$2:$A$97=$A23),(Colles!C$2:C$97=$B23),(Colles!$B$2:$B$97))>0,sumproduct((Colles!$A$2:$A$97=$A23),(Colles!C$2:C$97=$B23),(Colles!$B$2:$B$97)),"") | H23: =if(sumproduct((Colles!$A$2:$A$97=$A23),(Colles!D$2:D$97=$B23),(Colles!$B$2:$B$97))>0,sumproduct((Colles!$A$2:$A$97=$A23),(Colles!D$2:D$97=$B23),(Colles!$B$2:$B$97)),"") -> 7 | I23: =if(sumproduct((Colles!$A$2:$A$97=$A23),(Colles!E$2:E$97=$B23),(Colles!$B$2:$B$97))>0,sumproduct((Colles!$A$2:$A$97=$A23),(Colles!E$2:E$97=$B23),(Colles!$B$2:$B$97)),"") -> 10 | J23: =if(sumproduct((Colles!$A$2:$A$97=$A23),(Colles!F$2:F$97=$B23),(Colles!$B$2:$B$97))>0,sumproduct((Colles!$A$2:$A$97=$A23),(Colles!F$2:F$97=$B23),(Colles!$B$2:$B$97)),"") -> 3 | K23: =if(sumproduct((Colles!$A$2:$A$97=$A23),(Colles!G$2:G$97=$B23),(Colles!$B$2:$B$97))>0,sumproduct((Colles!$A$2:$A$97=$A23),(Colles!G$2:G$97=$B23),(Colles!$B$2:$B$97)),"") -> 16 | M23: =if(sumproduct((Colles!$A$2:$A$97=$A23),(Colles!I$2:I$97=$B23),(Colles!$B$2:$B$97))>0,sumproduct((Colles!$A$2:$A$97=$A23),(Colles!I$2:I$97=$B23),(Colles!$B$2:$B$97)),"") -> 1 | N23: =if(sumproduct((Colles!$A$2:$A$97=$A23),(Colles!J$2:J$97=$B23),(Colles!$B$2:$B$97))>0,sumproduct((Colles!$A$2:$A$97=$A23),(Colles!J$2:J$97=$B23),(Colles!$B$2:$B$97)),"") -> 14 | O23: =if(sumproduct((Colles!$A$2:$A$97=$A23),(Colles!K$2:K$97=$B23),(Colles!$B$2:$B$97))>0,sumproduct((Colles!$A$2:$A$97=$A23),(Colles!K$2:K$97=$B23),(Colles!$B$2:$B$97)),"") -> 3 | P23: =if(sumproduct((Colles!$A$2:$A$97=$A23),(Colles!L$2:L$97=$B23),(Colles!$B$2:$B$97))>0,sumproduct((Colles!$A$2:$A$97=$A23),(Colles!L$2:L$97=$B23),(Colles!$B$2:$B$97)),"") -> 12 | Q23: =if(sumproduct((Colles!$A$2:$A$97=$A23),(Colles!M$2:M$97=$B23),(Colles!$B$2:$B$97))>0,sumproduct((Colles!$A$2:$A$97=$A23),(Colles!M$2:M$97=$B23),(Colles!$B$2:$B$97)),"") -> 7 | R23: =if(sumproduct((Colles!$A$2:$A$97=$A23),(Colles!N$2:N$97=$B23),(Colles!$B$2:$B$97))>0,sumproduct((Colles!$A$2:$A$97=$A23),(Colles!N$2:N$97=$B23),(Colles!$B$2:$B$97)),"") -> 16 | S23: =if(sumproduct((Colles!$A$2:$A$97=$A23),(Colles!O$2:O$97=$B23),(Colles!$B$2:$B$97))>0,sumproduct((Colles!$A$2:$A$97=$A23),(Colles!O$2:O$97=$B23),(Colles!$B$2:$B$97)),"") -> 5 | U23: =if(sumproduct((Colles!$A$2:$A$97=$A23),(Colles!Q$2:Q$97=$B23),(Colles!$B$2:$B$97))>0,sumproduct((Colles!$A$2:$A$97=$A23),(Colles!Q$2:Q$97=$B23),(Colles!$B$2:$B$97)),"") | V23: =if(sumproduct((Colles!$A$2:$A$97=$A23),(Colles!R$2:R$97=$B23),(Colles!$B$2:$B$97))>0,sumproduct((Colles!$A$2:$A$97=$A23),(Colles!R$2:R$97=$B23),(Colles!$B$2:$B$97)),"") -> 8 | W23: =if(sumproduct((Colles!$A$2:$A$97=$A23),(Colles!S$2:S$97=$B23),(Colles!$B$2:$B$97))>0,sumproduct((Colles!$A$2:$A$97=$A23),(Colles!S$2:S$97=$B23),(Colles!$B$2:$B$97)),"") -> 13 | Y23: =Y22 -> 1 | Z23: {=IF(ISERROR(ADDRESS(SUMPRODUCT('Trinômes'!$B$2:$B$48=Y23,'Trinômes'!$C$2:$C$48=COUNTIF(Y$21:Y23,"="&Y23)-1 ,ROW('Trinômes'!$A$2:$A$48)),COLUMN('Trinômes'!$A$1)-COLUMN('Trinômes'!$A$1)+1)),"",indirect("Trinômes!"&ADDRESS(SUMPRODUCT('Trinômes'!$B$2:$B$48=Y23,'Trinômes'!$C$2:$C$48=COUNTIF(Y$21:Y23,"="&Y23)-1 ,ROW('Trinômes'!$A$2:$A$48)),COLUMN('Trinômes'!$A$1)-COLUMN('Trinômes'!$A$1)+1)))} -> ALEXANDRE Romeo | AA23: =AA22 -> 2 | AB23: {=IF(ISERROR(ADDRESS(SUMPRODUCT('Trinômes'!$B$2:$B$48=AA23,'Trinômes'!$C$2:$C$48=COUNTIF(AA$21:AA23,"="&AA23)-1 ,ROW('Trinômes'!$A$2:$A$48)),COLUMN('Trinômes'!$A$1)-COLUMN('Trinômes'!$A$1)+1)),"",indirect("Trinômes!"&ADDRESS(SUMPRODUCT('Trinômes'!$B$2:$B$48=AA23,'Trinômes'!$C$2:$C$48=COUNTIF(AA$21:AA23,"="&AA23)-1 ,ROW('Trinômes'!$A$2:$A$48)),COLUMN('Trinômes'!$A$1)-COLUMN('Trinômes'!$A$1)+1)))} -> BOURDIER Alexandre
A24: ='Créneaux'!I7 -> Mathématiques | B24: ='Créneaux'!J7 -> 6 | C24: ='Créneaux'!K7 -> Mme Peyrelevade | D24: =switch('Créneaux'!L7,0,"Lundi",1,"Mardi",2,"Mercredi",3,"Jeudi",4,"Vendredi") -> Jeudi | E24: ='Créneaux'!M7&"h" -> 13h | F24: ='Créneaux'!N7 -> K22 | G24: =if(sumproduct((Colles!$A$2:$A$97=$A24),(Colles!C$2:C$97=$B24),(Colles!$B$2:$B$97))>0,sumproduct((Colles!$A$2:$A$97=$A24),(Colles!C$2:C$97=$B24),(Colles!$B$2:$B$97)),"") | H24: =if(sumproduct((Colles!$A$2:$A$97=$A24),(Colles!D$2:D$97=$B24),(Colles!$B$2:$B$97))>0,sumproduct((Colles!$A$2:$A$97=$A24),(Colles!D$2:D$97=$B24),(Colles!$B$2:$B$97)),"") -> 9 | I24: =if(sumproduct((Colles!$A$2:$A$97=$A24),(Colles!E$2:E$97=$B24),(Colles!$B$2:$B$97))>0,sumproduct((Colles!$A$2:$A$97=$A24),(Colles!E$2:E$97=$B24),(Colles!$B$2:$B$97)),"") -> 2 | J24: =if(sumproduct((Colles!$A$2:$A$97=$A24),(Colles!F$2:F$97=$B24),(Colles!$B$2:$B$97))>0,sumproduct((Colles!$A$2:$A$97=$A24),(Colles!F$2:F$97=$B24),(Colles!$B$2:$B$97)),"") -> 15 | K24: =if(sumproduct((Colles!$A$2:$A$97=$A24),(Colles!G$2:G$97=$B24),(Colles!$B$2:$B$97))>0,sumproduct((Colles!$A$2:$A$97=$A24),(Colles!G$2:G$97=$B24),(Colles!$B$2:$B$97)),"") -> 4 | M24: =if(sumproduct((Colles!$A$2:$A$97=$A24),(Colles!I$2:I$97=$B24),(Colles!$B$2:$B$97))>0,sumproduct((Colles!$A$2:$A$97=$A24),(Colles!I$2:I$97=$B24),(Colles!$B$2:$B$97)),"") -> 7 | N24: =if(sumproduct((Colles!$A$2:$A$97=$A24),(Colles!J$2:J$97=$B24),(Colles!$B$2:$B$97))>0,sumproduct((Colles!$A$2:$A$97=$A24),(Colles!J$2:J$97=$B24),(Colles!$B$2:$B$97)),"") -> 6 | O24: =if(sumproduct((Colles!$A$2:$A$97=$A24),(Colles!K$2:K$97=$B24),(Colles!$B$2:$B$97))>0,sumproduct((Colles!$A$2:$A$97=$A24),(Colles!K$2:K$97=$B24),(Colles!$B$2:$B$97)),"") -> 15 | P24: =if(sumproduct((Colles!$A$2:$A$97=$A24),(Colles!L$2:L$97=$B24),(Colles!$B$2:$B$97))>0,sumproduct((Colles!$A$2:$A$97=$A24),(Colles!L$2:L$97=$B24),(Colles!$B$2:$B$97)),"") -> 8 | Q24: =if(sumproduct((Colles!$A$2:$A$97=$A24),(Colles!M$2:M$97=$B24),(Colles!$B$2:$B$97))>0,sumproduct((Colles!$A$2:$A$97=$A24),(Colles!M$2:M$97=$B24),(Colles!$B$2:$B$97)),"") -> 9 | R24: =if(sumproduct((Colles!$A$2:$A$97=$A24),(Colles!N$2:N$97=$B24),(Colles!$B$2:$B$97))>0,sumproduct((Colles!$A$2:$A$97=$A24),(Colles!N$2:N$97=$B24),(Colles!$B$2:$B$97)),"") -> 2 | S24: =if(sumproduct((Colles!$A$2:$A$97=$A24),(Colles!O$2:O$97=$B24),(Colles!$B$2:$B$97))>0,sumproduct((Colles!$A$2:$A$97=$A24),(Colles!O$2:O$97=$B24),(Colles!$B$2:$B$97)),"") -> 15 | U24: =if(sumproduct((Colles!$A$2:$A$97=$A24),(Colles!Q$2:Q$97=$B24),(Colles!$B$2:$B$97))>0,sumproduct((Colles!$A$2:$A$97=$A24),(Colles!Q$2:Q$97=$B24),(Colles!$B$2:$B$97)),"") | V24: =if(sumproduct((Colles!$A$2:$A$97=$A24),(Colles!R$2:R$97=$B24),(Colles!$B$2:$B$97))>0,sumproduct((Colles!$A$2:$A$97=$A24),(Colles!R$2:R$97=$B24),(Colles!$B$2:$B$97)),"") -> 14 | W24: =if(sumproduct((Colles!$A$2:$A$97=$A24),(Colles!S$2:S$97=$B24),(Colles!$B$2:$B$97))>0,sumproduct((Colles!$A$2:$A$97=$A24),(Colles!S$2:S$97=$B24),(Colles!$B$2:$B$97)),"") -> 7 | Y24: =Y23 -> 1 | Z24: {=IF(ISERROR(ADDRESS(SUMPRODUCT('Trinômes'!$B$2:$B$48=Y24,'Trinômes'!$C$2:$C$48=COUNTIF(Y$21:Y24,"="&Y24)-1 ,ROW('Trinômes'!$A$2:$A$48)),COLUMN('Trinômes'!$A$1)-COLUMN('Trinômes'!$A$1)+1)),"",indirect("Trinômes!"&ADDRESS(SUMPRODUCT('Trinômes'!$B$2:$B$48=Y24,'Trinômes'!$C$2:$C$48=COUNTIF(Y$21:Y24,"="&Y24)-1 ,ROW('Trinômes'!$A$2:$A$48)),COLUMN('Trinômes'!$A$1)-COLUMN('Trinômes'!$A$1)+1)))} -> BIGATI Jules | AA24: =AA23 -> 2 | AB24: {=IF(ISERROR(ADDRESS(SUMPRODUCT('Trinômes'!$B$2:$B$48=AA24,'Trinômes'!$C$2:$C$48=COUNTIF(AA$21:AA24,"="&AA24)-1 ,ROW('Trinômes'!$A$2:$A$48)),COLUMN('Trinômes'!$A$1)-COLUMN('Trinômes'!$A$1)+1)),"",indirect("Trinômes!"&ADDRESS(SUMPRODUCT('Trinômes'!$B$2:$B$48=AA24,'Trinômes'!$C$2:$C$48=COUNTIF(AA$21:AA24,"="&AA24)-1 ,ROW('Trinômes'!$A$2:$A$48)),COLUMN('Trinômes'!$A$1)-COLUMN('Trinômes'!$A$1)+1)))} -> BROWNE Nora
A25: ='Créneaux'!I8 -> Mathématiques | B25: ='Créneaux'!J8 -> 7 | C25: ='Créneaux'!K8 -> Mme Royer | D25: =switch('Créneaux'!L8,0,"Lundi",1,"Mardi",2,"Mercredi",3,"Jeudi",4,"Vendredi") -> Jeudi | E25: ='Créneaux'!M8&"h" -> 17h | F25: ='Créneaux'!N8 -> Prépa 22 | G25: =if(sumproduct((Colles!$A$2:$A$97=$A25),(Colles!C$2:C$97=$B25),(Colles!$B$2:$B$97))>0,sumproduct((Colles!$A$2:$A$97=$A25),(Colles!C$2:C$97=$B25),(Colles!$B$2:$B$97)),"") | H25: =if(sumproduct((Colles!$A$2:$A$97=$A25),(Colles!D$2:D$97=$B25),(Colles!$B$2:$B$97))>0,sumproduct((Colles!$A$2:$A$97=$A25),(Colles!D$2:D$97=$B25),(Colles!$B$2:$B$97)),"") -> 13 | I25: =if(sumproduct((Colles!$A$2:$A$97=$A25),(Colles!E$2:E$97=$B25),(Colles!$B$2:$B$97))>0,sumproduct((Colles!$A$2:$A$97=$A25),(Colles!E$2:E$97=$B25),(Colles!$B$2:$B$97)),"") -> 8 | J25: =if(sumproduct((Colles!$A$2:$A$97=$A25),(Colles!F$2:F$97=$B25),(Colles!$B$2:$B$97))>0,sumproduct((Colles!$A$2:$A$97=$A25),(Colles!F$2:F$97=$B25),(Colles!$B$2:$B$97)),"") -> 11 | K25: =if(sumproduct((Colles!$A$2:$A$97=$A25),(Colles!G$2:G$97=$B25),(Colles!$B$2:$B$97))>0,sumproduct((Colles!$A$2:$A$97=$A25),(Colles!G$2:G$97=$B25),(Colles!$B$2:$B$97)),"") -> 2 | M25: =if(sumproduct((Colles!$A$2:$A$97=$A25),(Colles!I$2:I$97=$B25),(Colles!$B$2:$B$97))>0,sumproduct((Colles!$A$2:$A$97=$A25),(Colles!I$2:I$97=$B25),(Colles!$B$2:$B$97)),"") -> 9 | N25: =if(sumproduct((Colles!$A$2:$A$97=$A25),(Colles!J$2:J$97=$B25),(Colles!$B$2:$B$97))>0,sumproduct((Colles!$A$2:$A$97=$A25),(Colles!J$2:J$97=$B25),(Colles!$B$2:$B$97)),"") -> 4 | O25: =if(sumproduct((Colles!$A$2:$A$97=$A25),(Colles!K$2:K$97=$B25),(Colles!$B$2:$B$97))>0,sumproduct((Colles!$A$2:$A$97=$A25),(Colles!K$2:K$97=$B25),(Colles!$B$2:$B$97)),"") -> 11 | P25: =if(sumproduct((Colles!$A$2:$A$97=$A25),(Colles!L$2:L$97=$B25),(Colles!$B$2:$B$97))>0,sumproduct((Colles!$A$2:$A$97=$A25),(Colles!L$2:L$97=$B25),(Colles!$B$2:$B$97)),"") -> 6 | Q25: =if(sumproduct((Colles!$A$2:$A$97=$A25),(Colles!M$2:M$97=$B25),(Colles!$B$2:$B$97))>0,sumproduct((Colles!$A$2:$A$97=$A25),(Colles!M$2:M$97=$B25),(Colles!$B$2:$B$97)),"") -> 13 | R25: =if(sumproduct((Colles!$A$2:$A$97=$A25),(Colles!N$2:N$97=$B25),(Colles!$B$2:$B$97))>0,sumproduct((Colles!$A$2:$A$97=$A25),(Colles!N$2:N$97=$B25),(Colles!$B$2:$B$97)),"") -> 8 | S25: =if(sumproduct((Colles!$A$2:$A$97=$A25),(Colles!O$2:O$97=$B25),(Colles!$B$2:$B$97))>0,sumproduct((Colles!$A$2:$A$97=$A25),(Colles!O$2:O$97=$B25),(Colles!$B$2:$B$97)),"") -> 11 | U25: =if(sumproduct((Colles!$A$2:$A$97=$A25),(Colles!Q$2:Q$97=$B25),(Colles!$B$2:$B$97))>0,sumproduct((Colles!$A$2:$A$97=$A25),(Colles!Q$2:Q$97=$B25),(Colles!$B$2:$B$97)),"") | V25: =if(sumproduct((Colles!$A$2:$A$97=$A25),(Colles!R$2:R$97=$B25),(Colles!$B$2:$B$97))>0,sumproduct((Colles!$A$2:$A$97=$A25),(Colles!R$2:R$97=$B25),(Colles!$B$2:$B$97)),"") -> 12 | W25: =if(sumproduct((Colles!$A$2:$A$97=$A25),(Colles!S$2:S$97=$B25),(Colles!$B$2:$B$97))>0,sumproduct((Colles!$A$2:$A$97=$A25),(Colles!S$2:S$97=$B25),(Colles!$B$2:$B$97)),"") -> 5 | Y25: =Y24 -> 1 | AA25: =AA24 -> 2
A26: ='Créneaux'!I9 -> Mathématiques | B26: ='Créneaux'!J9 -> 8 | C26: ='Créneaux'!K9 -> Mme Royer | D26: =switch('Créneaux'!L9,0,"Lundi",1,"Mardi",2,"Mercredi",3,"Jeudi",4,"Vendredi") -> Jeudi | E26: ='Créneaux'!M9&"h" -> 18h | F26: ='Créneaux'!N9 -> Prépa 22 | G26: =if(sumproduct((Colles!$A$2:$A$97=$A26),(Colles!C$2:C$97=$B26),(Colles!$B$2:$B$97))>0,sumproduct((Colles!$A$2:$A$97=$A26),(Colles!C$2:C$97=$B26),(Colles!$B$2:$B$97)),"") | H26: =if(sumproduct((Colles!$A$2:$A$97=$A26),(Colles!D$2:D$97=$B26),(Colles!$B$2:$B$97))>0,sumproduct((Colles!$A$2:$A$97=$A26),(Colles!D$2:D$97=$B26),(Colles!$B$2:$B$97)),"") -> 5 | I26: =if(sumproduct((Colles!$A$2:$A$97=$A26),(Colles!E$2:E$97=$B26),(Colles!$B$2:$B$97))>0,sumproduct((Colles!$A$2:$A$97=$A26),(Colles!E$2:E$97=$B26),(Colles!$B$2:$B$97)),"") -> 12 | J26: =if(sumproduct((Colles!$A$2:$A$97=$A26),(Colles!F$2:F$97=$B26),(Colles!$B$2:$B$97))>0,sumproduct((Colles!$A$2:$A$97=$A26),(Colles!F$2:F$97=$B26),(Colles!$B$2:$B$97)),"") -> 1 | K26: =if(sumproduct((Colles!$A$2:$A$97=$A26),(Colles!G$2:G$97=$B26),(Colles!$B$2:$B$97))>0,sumproduct((Colles!$A$2:$A$97=$A26),(Colles!G$2:G$97=$B26),(Colles!$B$2:$B$97)),"") -> 14 | M26: =if(sumproduct((Colles!$A$2:$A$97=$A26),(Colles!I$2:I$97=$B26),(Colles!$B$2:$B$97))>0,sumproduct((Colles!$A$2:$A$97=$A26),(Colles!I$2:I$97=$B26),(Colles!$B$2:$B$97)),"") -> 3 | N26: =if(sumproduct((Colles!$A$2:$A$97=$A26),(Colles!J$2:J$97=$B26),(Colles!$B$2:$B$97))>0,sumproduct((Colles!$A$2:$A$97=$A26),(Colles!J$2:J$97=$B26),(Colles!$B$2:$B$97)),"") -> 12 | O26: =if(sumproduct((Colles!$A$2:$A$97=$A26),(Colles!K$2:K$97=$B26),(Colles!$B$2:$B$97))>0,sumproduct((Colles!$A$2:$A$97=$A26),(Colles!K$2:K$97=$B26),(Colles!$B$2:$B$97)),"") -> 1 | P26: =if(sumproduct((Colles!$A$2:$A$97=$A26),(Colles!L$2:L$97=$B26),(Colles!$B$2:$B$97))>0,sumproduct((Colles!$A$2:$A$97=$A26),(Colles!L$2:L$97=$B26),(Colles!$B$2:$B$97)),"") -> 10 | Q26: =if(sumproduct((Colles!$A$2:$A$97=$A26),(Colles!M$2:M$97=$B26),(Colles!$B$2:$B$97))>0,sumproduct((Colles!$A$2:$A$97=$A26),(Colles!M$2:M$97=$B26),(Colles!$B$2:$B$97)),"") -> 5 | R26: =if(sumproduct((Colles!$A$2:$A$97=$A26),(Colles!N$2:N$97=$B26),(Colles!$B$2:$B$97))>0,sumproduct((Colles!$A$2:$A$97=$A26),(Colles!N$2:N$97=$B26),(Colles!$B$2:$B$97)),"") -> 12 | S26: =if(sumproduct((Colles!$A$2:$A$97=$A26),(Colles!O$2:O$97=$B26),(Colles!$B$2:$B$97))>0,sumproduct((Colles!$A$2:$A$97=$A26),(Colles!O$2:O$97=$B26),(Colles!$B$2:$B$97)),"") -> 1 | U26: =if(sumproduct((Colles!$A$2:$A$97=$A26),(Colles!Q$2:Q$97=$B26),(Colles!$B$2:$B$97))>0,sumproduct((Colles!$A$2:$A$97=$A26),(Colles!Q$2:Q$97=$B26),(Colles!$B$2:$B$97)),"") | V26: =if(sumproduct((Colles!$A$2:$A$97=$A26),(Colles!R$2:R$97=$B26),(Colles!$B$2:$B$97))>0,sumproduct((Colles!$A$2:$A$97=$A26),(Colles!R$2:R$97=$B26),(Colles!$B$2:$B$97)),"") -> 6 | W26: =if(sumproduct((Colles!$A$2:$A$97=$A26),(Colles!S$2:S$97=$B26),(Colles!$B$2:$B$97))>0,sumproduct((Colles!$A$2:$A$97=$A26),(Colles!S$2:S$97=$B26),(Colles!$B$2:$B$97)),"") -> 11 | Y26: =AA21+1 -> 3 | Z26: =Y26&IF(SUMPRODUCT('Trinômes'!$A$2:$A$48=Z27,'Trinômes'!$D$2:$D$48<>0)+SUMPRODUCT('Trinômes'!$A$2:$A$48=Z28,'Trinômes'!$D$2:$D$48<>0)+SUMPRODUCT('Trinômes'!$A$2:$A$48=Z29,'Trinômes'!$D$2:$D$48<>0)>0," – LV2","") -> 3 | AA26: =Y26+1 -> 4 | AB26: =AA26&IF(SUMPRODUCT('Trinômes'!$A$2:$A$48=AB27,'Trinômes'!$D$2:$D$48<>0)+SUMPRODUCT('Trinômes'!$A$2:$A$48=AB28,'Trinômes'!$D$2:$D$48<>0)+SUMPRODUCT('Trinômes'!$A$2:$A$48=AB29,'Trinômes'!$D$2:$D$48<>0)>0," – LV2","") -> 4
C27: =A28 -> Anglais | Y27: =Y26 -> 3 | Z27: {=IF(ISERROR(ADDRESS(SUMPRODUCT('Trinômes'!$B$2:$B$48=Y27,'Trinômes'!$C$2:$C$48=COUNTIF(Y$21:Y27,"="&Y27)-1 ,ROW('Trinômes'!$A$2:$A$48)),COLUMN('Trinômes'!$A$1)-COLUMN('Trinômes'!$A$1)+1)),"",indirect("Trinômes!"&ADDRESS(SUMPRODUCT('Trinômes'!$B$2:$B$48=Y27,'Trinômes'!$C$2:$C$48=COUNTIF(Y$21:Y27,"="&Y27)-1 ,ROW('Trinômes'!$A$2:$A$48)),COLUMN('Trinômes'!$A$1)-COLUMN('Trinômes'!$A$1)+1)))} -> BUGEA--GENOVESE Gaëtan | AA27: =AA26 -> 4 | AB27: {=IF(ISERROR(ADDRESS(SUMPRODUCT('Trinômes'!$B$2:$B$48=AA27,'Trinômes'!$C$2:$C$48=COUNTIF(AA$21:AA27,"="&AA27)-1 ,ROW('Trinômes'!$A$2:$A$48)),COLUMN('Trinômes'!$A$1)-COLUMN('Trinômes'!$A$1)+1)),"",indirect("Trinômes!"&ADDRESS(SUMPRODUCT('Trinômes'!$B$2:$B$48=AA27,'Trinômes'!$C$2:$C$48=COUNTIF(AA$21:AA27,"="&AA27)-1 ,ROW('Trinômes'!$A$2:$A$48)),COLUMN('Trinômes'!$A$1)-COLUMN('Trinômes'!$A$1)+1)))} -> CASTAGNER Hugo
A28: ='Créneaux'!I10 -> Anglais | B28: ='Créneaux'!J10 -> 1 | C28: ='Créneaux'!K10 -> Mme Calvin | D28: =switch('Créneaux'!L10,0,"Lundi",1,"Mardi",2,"Mercredi",3,"Jeudi",4,"Vendredi") -> Lundi | E28: ='Créneaux'!M10&"h" -> 16h | F28: ='Créneaux'!N10 -> Prépa 14 | G28: =if(sumproduct((Colles!$A$2:$A$97=$A28),(Colles!C$2:C$97=$B28),(Colles!$B$2:$B$97))>0,sumproduct((Colles!$A$2:$A$97=$A28),(Colles!C$2:C$97=$B28),(Colles!$B$2:$B$97)),"") | H28: =if(sumproduct((Colles!$A$2:$A$97=$A28),(Colles!D$2:D$97=$B28),(Colles!$B$2:$B$97))>0,sumproduct((Colles!$A$2:$A$97=$A28),(Colles!D$2:D$97=$B28),(Colles!$B$2:$B$97)),"") -> 9 | I28: =if(sumproduct((Colles!$A$2:$A$97=$A28),(Colles!E$2:E$97=$B28),(Colles!$B$2:$B$97))>0,sumproduct((Colles!$A$2:$A$97=$A28),(Colles!E$2:E$97=$B28),(Colles!$B$2:$B$97)),"") -> 2 | J28: =if(sumproduct((Colles!$A$2:$A$97=$A28),(Colles!F$2:F$97=$B28),(Colles!$B$2:$B$97))>0,sumproduct((Colles!$A$2:$A$97=$A28),(Colles!F$2:F$97=$B28),(Colles!$B$2:$B$97)),"") -> 15 | K28: =if(sumproduct((Colles!$A$2:$A$97=$A28),(Colles!G$2:G$97=$B28),(Colles!$B$2:$B$97))>0,sumproduct((Colles!$A$2:$A$97=$A28),(Colles!G$2:G$97=$B28),(Colles!$B$2:$B$97)),"") -> 4 | M28: =if(sumproduct((Colles!$A$2:$A$97=$A28),(Colles!I$2:I$97=$B28),(Colles!$B$2:$B$97))>0,sumproduct((Colles!$A$2:$A$97=$A28),(Colles!I$2:I$97=$B28),(Colles!$B$2:$B$97)),"") -> 7 | N28: =if(sumproduct((Colles!$A$2:$A$97=$A28),(Colles!J$2:J$97=$B28),(Colles!$B$2:$B$97))>0,sumproduct((Colles!$A$2:$A$97=$A28),(Colles!J$2:J$97=$B28),(Colles!$B$2:$B$97)),"") -> 6 | O28: =if(sumproduct((Colles!$A$2:$A$97=$A28),(Colles!K$2:K$97=$B28),(Colles!$B$2:$B$97))>0,sumproduct((Colles!$A$2:$A$97=$A28),(Colles!K$2:K$97=$B28),(Colles!$B$2:$B$97)),"") -> 15 | P28: =if(sumproduct((Colles!$A$2:$A$97=$A28),(Colles!L$2:L$97=$B28),(Colles!$B$2:$B$97))>0,sumproduct((Colles!$A$2:$A$97=$A28),(Colles!L$2:L$97=$B28),(Colles!$B$2:$B$97)),"") -> 8 | Q28: =if(sumproduct((Colles!$A$2:$A$97=$A28),(Colles!M$2:M$97=$B28),(Colles!$B$2:$B$97))>0,sumproduct((Colles!$A$2:$A$97=$A28),(Colles!M$2:M$97=$B28),(Colles!$B$2:$B$97)),"") -> 9 | R28: =if(sumproduct((Colles!$A$2:$A$97=$A28),(Colles!N$2:N$97=$B28),(Colles!$B$2:$B$97))>0,sumproduct((Colles!$A$2:$A$97=$A28),(Colles!N$2:N$97=$B28),(Colles!$B$2:$B$97)),"") -> 2 | S28: =if(sumproduct((Colles!$A$2:$A$97=$A28),(Colles!O$2:O$97=$B28),(Colles!$B$2:$B$97))>0,sumproduct((Colles!$A$2:$A$97=$A28),(Colles!O$2:O$97=$B28),(Colles!$B$2:$B$97)),"") -> 15 | U28: =if(sumproduct((Colles!$A$2:$A$97=$A28),(Colles!Q$2:Q$97=$B28),(Colles!$B$2:$B$97))>0,sumproduct((Colles!$A$2:$A$97=$A28),(Colles!Q$2:Q$97=$B28),(Colles!$B$2:$B$97)),"") | V28: =if(sumproduct((Colles!$A$2:$A$97=$A28),(Colles!R$2:R$97=$B28),(Colles!$B$2:$B$97))>0,sumproduct((Colles!$A$2:$A$97=$A28),(Colles!R$2:R$97=$B28),(Colles!$B$2:$B$97)),"") -> 14 | W28: =if(sumproduct((Colles!$A$2:$A$97=$A28),(Colles!S$2:S$97=$B28),(Colles!$B$2:$B$97))>0,sumproduct((Colles!$A$2:$A$97=$A28),(Colles!S$2:S$97=$B28),(Colles!$B$2:$B$97)),"") -> 7 | Y28: =Y27 -> 3 | Z28: {=IF(ISERROR(ADDRESS(SUMPRODUCT('Trinômes'!$B$2:$B$48=Y28,'Trinômes'!$C$2:$C$48=COUNTIF(Y$21:Y28,"="&Y28)-1 ,ROW('Trinômes'!$A$2:$A$48)),COLUMN('Trinômes'!$A$1)-COLUMN('Trinômes'!$A$1)+1)),"",indirect("Trinômes!"&ADDRESS(SUMPRODUCT('Trinômes'!$B$2:$B$48=Y28,'Trinômes'!$C$2:$C$48=COUNTIF(Y$21:Y28,"="&Y28)-1 ,ROW('Trinômes'!$A$2:$A$48)),COLUMN('Trinômes'!$A$1)-COLUMN('Trinômes'!$A$1)+1)))} -> CALISTI Ange | AA28: =AA27 -> 4 | AB28: {=IF(ISERROR(ADDRESS(SUMPRODUCT('Trinômes'!$B$2:$B$48=AA28,'Trinômes'!$C$2:$C$48=COUNTIF(AA$21:AA28,"="&AA28)-1 ,ROW('Trinômes'!$A$2:$A$48)),COLUMN('Trinômes'!$A$1)-COLUMN('Trinômes'!$A$1)+1)),"",indirect("Trinômes!"&ADDRESS(SUMPRODUCT('Trinômes'!$B$2:$B$48=AA28,'Trinômes'!$C$2:$C$48=COUNTIF(AA$21:AA28,"="&AA28)-1 ,ROW('Trinômes'!$A$2:$A$48)),COLUMN('Trinômes'!$A$1)-COLUMN('Trinômes'!$A$1)+1)))} -> CATHALA Andrea
A29: ='Créneaux'!I11 -> Anglais | B29: ='Créneaux'!J11 -> 2 | C29: ='Créneaux'!K11 -> Mme Calvin | D29: =switch('Créneaux'!L11,0,"Lundi",1,"Mardi",2,"Mercredi",3,"Jeudi",4,"Vendredi") -> Mercredi | E29: ='Créneaux'!M11&"h" -> 15h | F29: ='Créneaux'!N11 -> K25 | G29: =if(sumproduct((Colles!$A$2:$A$97=$A29),(Colles!C$2:C$97=$B29),(Colles!$B$2:$B$97))>0,sumproduct((Colles!$A$2:$A$97=$A29),(Colles!C$2:C$97=$B29),(Colles!$B$2:$B$97)),"") | H29: =if(sumproduct((Colles!$A$2:$A$97=$A29),(Colles!D$2:D$97=$B29),(Colles!$B$2:$B$97))>0,sumproduct((Colles!$A$2:$A$97=$A29),(Colles!D$2:D$97=$B29),(Colles!$B$2:$B$97)),"") -> 5 | I29: =if(sumproduct((Colles!$A$2:$A$97=$A29),(Colles!E$2:E$97=$B29),(Colles!$B$2:$B$97))>0,sumproduct((Colles!$A$2:$A$97=$A29),(Colles!E$2:E$97=$B29),(Colles!$B$2:$B$97)),"") -> 12 | J29: =if(sumproduct((Colles!$A$2:$A$97=$A29),(Colles!F$2:F$97=$B29),(Colles!$B$2:$B$97))>0,sumproduct((Colles!$A$2:$A$97=$A29),(Colles!F$2:F$97=$B29),(Colles!$B$2:$B$97)),"") -> 1 | K29: =if(sumproduct((Colles!$A$2:$A$97=$A29),(Colles!G$2:G$97=$B29),(Colles!$B$2:$B$97))>0,sumproduct((Colles!$A$2:$A$97=$A29),(Colles!G$2:G$97=$B29),(Colles!$B$2:$B$97)),"") -> 16 | M29: =if(sumproduct((Colles!$A$2:$A$97=$A29),(Colles!I$2:I$97=$B29),(Colles!$B$2:$B$97))>0,sumproduct((Colles!$A$2:$A$97=$A29),(Colles!I$2:I$97=$B29),(Colles!$B$2:$B$97)),"") -> 3 | N29: =if(sumproduct((Colles!$A$2:$A$97=$A29),(Colles!J$2:J$97=$B29),(Colles!$B$2:$B$97))>0,sumproduct((Colles!$A$2:$A$97=$A29),(Colles!J$2:J$97=$B29),(Colles!$B$2:$B$97)),"") -> 12 | O29: =if(sumproduct((Colles!$A$2:$A$97=$A29),(Colles!K$2:K$97=$B29),(Colles!$B$2:$B$97))>0,sumproduct((Colles!$A$2:$A$97=$A29),(Colles!K$2:K$97=$B29),(Colles!$B$2:$B$97)),"") -> 1 | P29: =if(sumproduct((Colles!$A$2:$A$97=$A29),(Colles!L$2:L$97=$B29),(Colles!$B$2:$B$97))>0,sumproduct((Colles!$A$2:$A$97=$A29),(Colles!L$2:L$97=$B29),(Colles!$B$2:$B$97)),"") -> 10 | Q29: =if(sumproduct((Colles!$A$2:$A$97=$A29),(Colles!M$2:M$97=$B29),(Colles!$B$2:$B$97))>0,sumproduct((Colles!$A$2:$A$97=$A29),(Colles!M$2:M$97=$B29),(Colles!$B$2:$B$97)),"") -> 5 | R29: =if(sumproduct((Colles!$A$2:$A$97=$A29),(Colles!N$2:N$97=$B29),(Colles!$B$2:$B$97))>0,sumproduct((Colles!$A$2:$A$97=$A29),(Colles!N$2:N$97=$B29),(Colles!$B$2:$B$97)),"") -> 12 | S29: =if(sumproduct((Colles!$A$2:$A$97=$A29),(Colles!O$2:O$97=$B29),(Colles!$B$2:$B$97))>0,sumproduct((Colles!$A$2:$A$97=$A29),(Colles!O$2:O$97=$B29),(Colles!$B$2:$B$97)),"") -> 1 | U29: =if(sumproduct((Colles!$A$2:$A$97=$A29),(Colles!Q$2:Q$97=$B29),(Colles!$B$2:$B$97))>0,sumproduct((Colles!$A$2:$A$97=$A29),(Colles!Q$2:Q$97=$B29),(Colles!$B$2:$B$97)),"") | V29: =if(sumproduct((Colles!$A$2:$A$97=$A29),(Colles!R$2:R$97=$B29),(Colles!$B$2:$B$97))>0,sumproduct((Colles!$A$2:$A$97=$A29),(Colles!R$2:R$97=$B29),(Colles!$B$2:$B$97)),"") -> 6 | W29: =if(sumproduct((Colles!$A$2:$A$97=$A29),(Colles!S$2:S$97=$B29),(Colles!$B$2:$B$97))>0,sumproduct((Colles!$A$2:$A$97=$A29),(Colles!S$2:S$97=$B29),(Colles!$B$2:$B$97)),"") -> 11 | Y29: =Y28 -> 3 | Z29: {=IF(ISERROR(ADDRESS(SUMPRODUCT('Trinômes'!$B$2:$B$48=Y29,'Trinômes'!$C$2:$C$48=COUNTIF(Y$21:Y29,"="&Y29)-1 ,ROW('Trinômes'!$A$2:$A$48)),COLUMN('Trinômes'!$A$1)-COLUMN('Trinômes'!$A$1)+1)),"",indirect("Trinômes!"&ADDRESS(SUMPRODUCT('Trinômes'!$B$2:$B$48=Y29,'Trinômes'!$C$2:$C$48=COUNTIF(Y$21:Y29,"="&Y29)-1 ,ROW('Trinômes'!$A$2:$A$48)),COLUMN('Trinômes'!$A$1)-COLUMN('Trinômes'!$A$1)+1)))} -> CARNAILLE Alexis | AA29: =AA28 -> 4 | AB29: {=IF(ISERROR(ADDRESS(SUMPRODUCT('Trinômes'!$B$2:$B$48=AA29,'Trinômes'!$C$2:$C$48=COUNTIF(AA$21:AA29,"="&AA29)-1 ,ROW('Trinômes'!$A$2:$A$48)),COLUMN('Trinômes'!$A$1)-COLUMN('Trinômes'!$A$1)+1)),"",indirect("Trinômes!"&ADDRESS(SUMPRODUCT('Trinômes'!$B$2:$B$48=AA29,'Trinômes'!$C$2:$C$48=COUNTIF(AA$21:AA29,"="&AA29)-1 ,ROW('Trinômes'!$A$2:$A$48)),COLUMN('Trinômes'!$A$1)-COLUMN('Trinômes'!$A$1)+1)))} -> CESARI Elia
